Workbook
Name FX: 'Price Basis'!$B$6
Name FX_Date: 'Price Basis'!$B$7
Name VAT: 'Price Basis'!$B$8
Name AMC_Rate: 'Price Basis'!$B$9
Name Esc: 'Price Basis'!$B$10
Name AMC_Start: 'Price Basis'!$B$11
Name Onboard_Pct: 'Price Basis'!$B$12
Name Infra_Esc: 'Price Basis'!$B$13
Name Days_per_LOB: 'Price Basis'!$B$14
Name Round_To: 'Price Basis'!$B$15
Name Validity: 'Price Basis'!$B$16
Name Blended: 'Price Basis'!$B$17
Name Rate_BA: 'Price Basis'!$B$18
Name Rate_Dev: 'Price Basis'!$B$19
Name Rate_QA: 'Price Basis'!$B$20
Name Rate_PM: 'Price Basis'!$B$21
Name Rate_Trainer: 'Price Basis'!$B$22
Name Rate_Onsite: 'Price Basis'!$B$23
Name TierName: 'Price Basis'!$A$27:$A$30
Name TierFrom: 'Price Basis'!$B$27:$B$30
Name TierTo: 'Price Basis'!$C$27:$C$30
Name PerpRate: 'Price Basis'!$D$27:$D$30
Name SubRate: 'Price Basis'!$E$27:$E$30
Name MinBill: 'Price Basis'!$F$27:$F$30
Name BaseDays: 'Price Basis'!$G$27:$G$30
Name LOBIncl: 'Price Basis'!$H$27:$H$30
Name TrainDays: 'Price Basis'!$I$27:$I$30
Name RefUsers: 'Price Basis'!$J$27:$J$30
Name Sup24: 'Price Basis'!$K$27:$K$30
Name Duration: 'Price Basis'!$L$27:$L$30
Name Host_Hdr: 'Price Basis'!$B$34:$E$34
Name Host_Tbl: 'Price Basis'!$B$35:$E$38
Name Env_Setup: 'Price Basis'!$B$43
Name Env_Month: 'Price Basis'!$B$44
Name Mig_Source: 'Price Basis'!$B$45
Name Mig_Day: 'Price Basis'!$B$46
Name Int_Std: 'Price Basis'!$B$47
Name Int_Cx: 'Price Basis'!$B$48
Name LOB_After: 'Price Basis'!$B$49
Name Report_Item: 'Price Basis'!$B$50
Name Disc_AM: Negotiation!$B$6
Name Disc_SH: Negotiation!$C$6
Name Disc_CEO: Negotiation!$D$6
Name Floor_SW: Negotiation!$E$6
Name Floor_Svc: Negotiation!$E$8
Name Host_AM: Negotiation!$B$10
Name Host_SH: Negotiation!$C$10
Name Host_CEO: Negotiation!$D$10
Name Floor_Host: Negotiation!$E$10

Sheet Read Me
A1: iNXT BrokerVerse OOTB: price book
A2: iorta TechNXT Corp. Prepared 03 October 2026. INTERNAL: contains discount limits and floor prices. Do not send this workbook to a client.
A4: Topic | B4: Notes
A5: Purpose | B5: Pre-set commercials for presentations and first quotations of iNXT BrokerVerse OOTB (the out-of-the-box, as-is version) to Philippine non-life insurance brokers. The presenter picks the size, licence model, hosting, term and options and the client sees the price on the spot.
A6: Source of prices | B6: Every price point comes from the recommended price points of the pricing workbook BrokerVerse_Commercials_and_Pricing.xlsx (Inputs, Infrastructure and Optional Services sheets), copied to the Price Basis sheet when this book was built. If the pricing workbook changes, rebuild this book with docs/package/tools/build_price_book.py. Do not type new prices here.
A7: Sheets | B7: Quick Quote: interactive quotation. Pre-set Packages: four ready packages per tier at list price and at the approved floor. Negotiation: approval matrix, floors and give/get levers (internal). Validity and Terms: validity, taxes and payment terms to read out with any quotation. Price Basis: the price points and drivers.
A8: How to use Quick Quote | B8: 1. Choose "Tier reference" and pick a tier, or choose "Custom" and type the user count and the number of lines of business. 2. Pick the licence model, hosting, contract term and optional services (yellow cells). 3. Leave the discount cells at 0% in front of the client. Any discount needs the approval shown in the result (Negotiation sheet). 4. Read the results and the payment schedule. The comparison block shows the other licence model with the same choices. 5. Recalculate (F9) if your spreadsheet tool does not recalculate on open.
A9: What to show the client | B9: Quick Quote at list price, the client columns of Pre-set Packages (list price only) and Validity and Terms. Never show the floor columns or the Negotiation sheet. The client-facing rate card is iNXT_BrokerVerse_Commercial_Proposal_Rate_Card.pdf.
A10: Prices and taxes | B10: All prices are in PHP and exclude 12% VAT. USD figures are for reference only at the exchange rate on Price Basis. Withholding tax deducted by the client does not reduce the invoice price; the client issues BIR Form 2307.
A11: Year convention | B11: Years are contract years counted from go-live, as in the pricing workbook. Implementation and the perpetual licence fall in Year 1. Subscription, hosting and 24x7 support are priced for 12 months in each year; AMC starts in the AMC start year (default Year 2, after a 12-month warranty). Recurring prices increase 5% at each anniversary; hosting follows the infrastructure change rate (default 0%).
A12: Colour key | B12: Yellow cell with blue text: input. Green: result. Light orange: internal only (discounts, floors). Navy header: column titles.

Sheet Quick Quote
A1: Quick Quote
A2: Pick the options in the yellow cells. PHP, exclusive of 12% VAT unless stated. Valid 90 days from the quotation date.
A4: Choices
A5: Choice | B5: Value | C5: Notes
A6: Client name | B6: [Client name] | C6: Shown on the quotation.
A7: Quotation date | B7: =DATE(2026,10,3) | C7: Valid until the date shown in the results.
A8: Sizing method | B8: Tier reference | C8: "Tier reference" uses the reference users and lines of business of the tier. "Custom" uses the two cells below.
A9: Tier (when sizing by tier reference) | B9: Medium | C9: Small 1 to 25 users, Medium 26 to 100, Large 101 to 300, Enterprise above 300.
A10: Named users (when Custom) | B10: 40 | C10: A user is a named person with a sign-in.
A11: Lines of business to configure (when Custom) | B11: 6 | C11: Motor, fire, marine, casualty, engineering, bonds and so on.
A12: Licence model | B12: Subscription | C12: Perpetual (one-time licence plus AMC) or Subscription (monthly).
A13: Hosting | B13: AWS | C13: Self-hosted, AWS, Azure or Local partner.
A14: Contract term (years) | B14: 3 | C14: 1, 3 or 5 years. The minimum subscription term is 12 months.
A15: 24x7 Severity 1 support | B15: No | C15: Standard support is 08:00 to 18:00 PHT, Monday to Friday.
A16: Extra training days | B16: 0 | C16: Beyond the days included for the tier.
A17: Legacy data sources to migrate | B17: 0 | C17: Beyond the standard upload templates.
A18: Additional standard integrations | B18: 0 | C18: One documented API or file exchange, one direction.
A19: Additional complex integrations | B19: 0 | C19: Two-way, no API, or batch with reconciliation.
A20: Additional environments (training or second UAT) | B20: 0 | C20: Set-up fee, plus a monthly fee when iorta TechNXT hosts.
A21: On-site consultant days (Metro Manila) | B21: 0 | C21: Remote delivery is the default.
A22: Discount on licence or subscription | B22: 0 | C22: INTERNAL. Leave at 0% in front of the client. Approval per the Negotiation sheet.
A23: Discount on implementation, services and 24x7 support | B23: 0 | C23: INTERNAL. As above.
A24: Discount on hosting | B24: 0 | C24: INTERNAL. As above.
A25: Named users used | B25: =IF($B$8="Custom",$B$10,INDEX(RefUsers,MATCH($B$9,TierName,0)))
A26: Lines of business used | B26: =IF($B$8="Custom",$B$11,INDEX(LOBIncl,MATCH($B$9,TierName,0)))
A28: Results
A29: Item | B29: PHP excl. VAT | C29: PHP incl. VAT | D29: USD reference | E29: Notes
A30: Tier | B30: =B101 | E30: ="Implementation about "&INDEX(Duration,B100)&"; "&B118&" training days included"
A31: One-time implementation fee (subscription: onboarding fee) | B31: =B105 | C31: =B31*(1+VAT) | D31: =B31/FX | E31: =B103&" man-days at the blended rate; "&$B$26&" lines of business"
A32: Perpetual licence fee (one-time, on go-live) | B32: =B107 | C32: =B32*(1+VAT) | D32: =B32/FX | E32: =IF($B$12="Perpetual",TEXT(B110,"#,##0")&" per user on average, graduated slabs","Not applicable to subscription")
A33: Subscription per month, Year 1 | B33: =B109 | C33: =B33*(1+VAT) | D33: =B33/FX | E33: =IF($B$12="Subscription",B102&" billable users, "&TEXT(B110,"#,##0")&" per user per month on average","Not applicable to perpetual")
A34: AMC per year, first AMC year | B34: =CHOOSE(MIN(AMC_Start,5),B119,B120,B121,B122,B123) | C34: =B34*(1+VAT) | D34: =B34/FX | E34: =IF($B$12="Perpetual","22% of the licence fee from Year "&AMC_Start&", then +5% a year","Not applicable: support is in the subscription")
A35: Hosting per month | B35: =B112+B113 | C35: =B35*(1+VAT) | D35: =B35/FX | E35: =$B$13&IF($B$20>0,", including "&$B$20&" additional environment(s)","")
A36: One-time optional services | B36: =B116 | C36: =B36*(1+VAT) | D36: =B36/FX | E36: Training, migration, integrations, environment set-up, on-site days chosen above.
A37: 24x7 Severity 1 support per year, Year 1 | B37: =B134 | C37: =B37*(1+VAT) | D37: =B37/FX | E37: Optional; +5% a year.
A38: Year 1 total | B38: =B139 | C38: =B38*(1+VAT) | D38: =B38/FX | E38: Everything payable in the first contract year.
A39: Total for the contract term | B39: =B144 | C39: =B39*(1+VAT) | D39: =B39/FX | E39: ="Contract term of "&$B$14&" year(s)"
A40: 5-year total cost | B40: =B145 | C40: =B40*(1+VAT) | D40: =B40/FX | E40: Assumes renewal to Year 5 at the escalated prices.
A41: Discount included in the 5-year total | B41: =C145-B145 | C41: =B41*(1+VAT) | D41: =B41/FX | E41: INTERNAL. 0 at list price.
A42: Approval needed for the discounts entered | B42: =CHOOSE(MAX(IF($B$22<=0,0,IF($B$22<=Disc_AM,1,IF($B$22<=Disc_SH,2,IF($B$22<=Disc_CEO,3,4)))),IF($B$23<=0,0,IF($B$23<=Disc_AM,1,IF($B$23<=Disc_SH,2,IF($B$23<=Disc_CEO,3,4)))),IF($B$24<=0,0,IF($B$24<=Host_AM,1,IF($B$24<=Host_SH,2,IF($B$24<=Host_CEO,3,4)))))+1,"None: list price","Account manager","Sales head","CEO","Not allowed: below the floor") | E42: INTERNAL. Limits on the Negotiation sheet.
...

Sheet Pre-set Packages
A1: Pre-set packages: four per tier, at list and at the approved floor
A2: Reference users and lines of business of each tier. PHP, exclusive of VAT. List columns may be shown to the client; floor columns are INTERNAL.
A4: Summary
A5: Tier and package | B5: One-time fees, list | C5: One-time fees, floor | D5: Monthly fees at go-live, list | E5: Monthly fees, floor | F5: Year 1 total, list | G5: Year 1 total, floor | H5: 5-year total, list | I5: 5-year total, floor
A6: Small: Essentials (subscription, Self-hosted) | B6: =B47+B49+B58 | C6: =C47+C49+C58 | D6: =B56 | E6: =C56 | F6: =B81 | G6: =C81 | H6: =B87 | I6: =C87
A7: Small: Standard (subscription, AWS) | B7: =D47+D49+D58 | C7: =E47+E49+E58 | D7: =D56 | E7: =E56 | F7: =D81 | G7: =E81 | H7: =D87 | I7: =E87
A8: Small: Ownership (perpetual, AWS) | B8: =F47+F49+F58 | C8: =G47+G49+G58 | D8: =F56 | E8: =G56 | F8: =F81 | G8: =G81 | H8: =F87 | I8: =G87
A9: Small: Ownership Plus (perpetual, Local partner) | B9: =H47+H49+H58 | C9: =I47+I49+I58 | D9: =H56 | E9: =I56 | F9: =H81 | G9: =I81 | H9: =H87 | I9: =I87
A10: Medium: Essentials (subscription, Self-hosted) | B10: =B115+B117+B126 | C10: =C115+C117+C126 | D10: =B124 | E10: =C124 | F10: =B149 | G10: =C149 | H10: =B155 | I10: =C155
A11: Medium: Standard (subscription, AWS) | B11: =D115+D117+D126 | C11: =E115+E117+E126 | D11: =D124 | E11: =E124 | F11: =D149 | G11: =E149 | H11: =D155 | I11: =E155
A12: Medium: Ownership (perpetual, AWS) | B12: =F115+F117+F126 | C12: =G115+G117+G126 | D12: =F124 | E12: =G124 | F12: =F149 | G12: =G149 | H12: =F155 | I12: =G155
A13: Medium: Ownership Plus (perpetual, Local partner) | B13: =H115+H117+H126 | C13: =I115+I117+I126 | D13: =H124 | E13: =I124 | F13: =H149 | G13: =I149 | H13: =H155 | I13: =I155
A14: Large: Essentials (subscription, Self-hosted) | B14: =B183+B185+B194 | C14: =C183+C185+C194 | D14: =B192 | E14: =C192 | F14: =B217 | G14: =C217 | H14: =B223 | I14: =C223
A15: Large: Standard (subscription, AWS) | B15: =D183+D185+D194 | C15: =E183+E185+E194 | D15: =D192 | E15: =E192 | F15: =D217 | G15: =E217 | H15: =D223 | I15: =E223
A16: Large: Ownership (perpetual, AWS) | B16: =F183+F185+F194 | C16: =G183+G185+G194 | D16: =F192 | E16: =G192 | F16: =F217 | G16: =G217 | H16: =F223 | I16: =G223
A17: Large: Ownership Plus (perpetual, Local partner) | B17: =H183+H185+H194 | C17: =I183+I185+I194 | D17: =H192 | E17: =I192 | F17: =H217 | G17: =I217 | H17: =H223 | I17: =I223
A18: Enterprise: Essentials (subscription, Self-hosted) | B18: =B251+B253+B262 | C18: =C251+C253+C262 | D18: =B260 | E18: =C260 | F18: =B285 | G18: =C285 | H18: =B291 | I18: =C291
A19: Enterprise: Standard (subscription, AWS) | B19: =D251+D253+D262 | C19: =E251+E253+E262 | D19: =D260 | E19: =E260 | F19: =D285 | G19: =E285 | H19: =D291 | I19: =E291
A20: Enterprise: Ownership (perpetual, AWS) | B20: =F251+F253+F262 | C20: =G251+G253+G262 | D20: =F260 | E20: =G260 | F20: =F285 | G20: =G285 | H20: =F291 | I20: =G291
A21: Enterprise: Ownership Plus (perpetual, Local partner) | B21: =H251+H253+H262 | C21: =I251+I253+I262 | D21: =H260 | E21: =I260 | F21: =H285 | G21: =I285 | H21: =H291 | I21: =I291
A22: One-time fees: implementation or onboarding, perpetual licence and one-time services. Monthly fees: subscription, hosting and additional environments. AMC (perpetual) and 24x7 support are yearly and are in the Year 1 and 5-year totals. Floor = CEO limit on every component.
A24: Small tier: 15 users, 5 lines of business
A25: Line | B25: Essentials, list | C25: Essentials, floor | D25: Standard, list | E25: Standard, floor | F25: Ownership, list | G25: Ownership, floor | H25: Ownership Plus, list | I25: Ownership Plus, floor
A26: What it is | B26: Subscription; the client hosts; standard support; 3-year term. | D26: Subscription hosted by iorta TechNXT on AWS (Singapore); 3-year term. | F26: Perpetual licence with AMC, hosted on AWS (Singapore); 5-year view. | H26: Perpetual with AMC, hosted in the Philippines, 24x7 Severity 1 support, 2 extra training days, 1 legacy source migrated.
A27: Named users | B27: ='Price Basis'!J27 | C27: ='Price Basis'!J27 | D27: ='Price Basis'!J27 | E27: ='Price Basis'!J27 | F27: ='Price Basis'!J27 | G27: ='Price Basis'!J27 | H27: ='Price Basis'!J27 | I27: ='Price Basis'!J27
A28: Lines of business | B28: ='Price Basis'!H27 | C28: ='Price Basis'!H27 | D28: ='Price Basis'!H27 | E28: ='Price Basis'!H27 | F28: ='Price Basis'!H27 | G28: ='Price Basis'!H27 | H28: ='Price Basis'!H27 | I28: ='Price Basis'!H27
A29: Licence model | B29: Subscription | C29: Subscription | D29: Subscription | E29: Subscription | F29: Perpetual | G29: Perpetual | H29: Perpetual | I29: Perpetual
A30: Hosting | B30: Self-hosted | C30: Self-hosted | D30: AWS | E30: AWS | F30: AWS | G30: AWS | H30: Local partner | I30: Local partner
A31: 24x7 Severity 1 support | B31: No | C31: No | D31: No | E31: No | F31: No | G31: No | H31: Yes | I31: Yes
A32: Extra training days | B32: 0 | C32: 0 | D32: 0 | E32: 0 | F32: 0 | G32: 0 | H32: 2 | I32: 2
A33: Legacy data sources migrated | B33: 0 | C33: 0 | D33: 0 | E33: 0 | F33: 0 | G33: 0 | H33: 1 | I33: 1
A34: Additional standard integrations | B34: 0 | C34: 0 | D34: 0 | E34: 0 | F34: 0 | G34: 0 | H34: 0 | I34: 0
A35: Additional complex integrations | B35: 0 | C35: 0 | D35: 0 | E35: 0 | F35: 0 | G35: 0 | H35: 0 | I35: 0
A36: Additional environments | B36: 0 | C36: 0 | D36: 0 | E36: 0 | F36: 0 | G36: 0 | H36: 0 | I36: 0
A37: On-site days | B37: 0 | C37: 0 | D37: 0 | E37: 0 | F37: 0 | G37: 0 | H37: 0 | I37: 0
A38: Contract term (years) | B38: 3 | C38: 3 | D38: 3 | E38: 3 | F38: 5 | G38: 5 | H38: 5 | I38: 5
A39: Discount on licence or subscription | B39: 0 | C39: =Floor_SW | D39: 0 | E39: =Floor_SW | F39: 0 | G39: =Floor_SW | H39: 0 | I39: =Floor_SW
A40: Discount on implementation and services | B40: 0 | C40: =Floor_Svc | D40: 0 | E40: =Floor_Svc | F40: 0 | G40: =Floor_Svc | H40: 0 | I40: =Floor_Svc
A41: Discount on hosting | B41: 0 | C41: =Floor_Host | D41: 0 | E41: =Floor_Host | F41: 0 | G41: =Floor_Host | H41: 0 | I41: =Floor_Host
A42: Tier index | B42: =MATCH($B$27,TierFrom,1) | C42: =MATCH($C$27,TierFrom,1) | D42: =MATCH($D$27,TierFrom,1) | E42: =MATCH($E$27,TierFrom,1) | F42: =MATCH($F$27,TierFrom,1) | G42: =MATCH($G$27,TierFrom,1) | H42: =MATCH($H$27,TierFrom,1) | I42: =MATCH($I$27,TierFrom,1)
...

Sheet Negotiation
A1: Negotiation: approval matrix, floors and levers
A2: INTERNAL. Never shown or sent to a client. Discounts are off the list price of each component.
A4: Approval matrix: maximum discount off list by approver
A5: Component | B5: Account manager | C5: Sales head | D5: CEO | E5: Floor: never below (discount) | F5: Floor as % of list | G5: Rules
A6: Perpetual licence fee | B6: 0.05 | C6: 0.1 | D6: 0.15 | E6: =D6 | F6: =1-E6 | G6: AMC follows the quoted (net) licence fee. AMC rate 22% and 5% escalation are not discounted (see levers).
A7: Subscription per user per month | B7: =B6 | C7: =C6 | D7: =D6 | E7: =E6 | F7: =1-E7 | G7: Discount fixed for the initial term; renewals at the then list price less the same discount unless agreed otherwise.
A8: Implementation or onboarding fee | B8: =B6 | C8: =C6 | D8: =D6 | E8: =D6 | F8: =1-E8 | G8: Reducing scope lowers the fee at the blended rate and is not a discount.
A9: One-time optional services and 24x7 support | B9: =B6 | C9: =C6 | D9: =D6 | E9: =E8 | F9: =1-E9 | G9: Same limits as implementation.
A10: Hosting per month | B10: 0 | C10: 0.05 | D10: 0.1 | E10: =D10 | F10: =1-E10 | G10: Hosting carries a 20% margin over estimated cloud cost; 10% off keeps about 8% for FX and operations.
A11: Change request and day rates | B11: 0 | C11: 0.05 | D11: 0.1 | E11: 0.1 | F11: =1-E11 | G11: Day rates are fixed for 12 months from signing. No discount on CRs below 5 man-days.
A12: AMC rate (22%) and escalation (5%) | B12: 0 | C12: 0 | D12: 0 | E12: 0 | F12: =1-E12 | G12: Not discounted. Only the multi-year AMC prepayment lever may hold the escalation, with CEO approval.
A13: The floor equals the CEO limit: nobody may approve a price below it. A deal that needs more must be restructured with the levers below (scope, phasing, term, payment) or declined. Total discount from all levers and discretion together may not pass the CEO limit.
A15: Floor prices per tier (reference users and lines of business)
A16: Tier | B16: Perpetual licence per user, list (first slab of tier) | C16: At floor | D16: Subscription per user per month, list | E16: At floor | F16: Implementation fee, list / at floor | G16: Hosting per month on AWS, list / at floor
A17: Small | B17: ='Price Basis'!D27 | C17: =B17*(1-Floor_SW) | D17: ='Price Basis'!E27 | E17: =D17*(1-Floor_SW) | F17: =TEXT(ROUND('Price Basis'!G27*Blended/Round_To,0)*Round_To,"#,##0")&" / "&TEXT(ROUND('Price Basis'!G27*Blended/Round_To,0)*Round_To*(1-Floor_Svc),"#,##0") | G17: =TEXT('Price Basis'!C35,"#,##0")&" / "&TEXT('Price Basis'!C35*(1-Floor_Host),"#,##0")
A18: Medium | B18: ='Price Basis'!D28 | C18: =B18*(1-Floor_SW) | D18: ='Price Basis'!E28 | E18: =D18*(1-Floor_SW) | F18: =TEXT(ROUND('Price Basis'!G28*Blended/Round_To,0)*Round_To,"#,##0")&" / "&TEXT(ROUND('Price Basis'!G28*Blended/Round_To,0)*Round_To*(1-Floor_Svc),"#,##0") | G18: =TEXT('Price Basis'!C36,"#,##0")&" / "&TEXT('Price Basis'!C36*(1-Floor_Host),"#,##0")
A19: Large | B19: ='Price Basis'!D29 | C19: =B19*(1-Floor_SW) | D19: ='Price Basis'!E29 | E19: =D19*(1-Floor_SW) | F19: =TEXT(ROUND('Price Basis'!G29*Blended/Round_To,0)*Round_To,"#,##0")&" / "&TEXT(ROUND('Price Basis'!G29*Blended/Round_To,0)*Round_To*(1-Floor_Svc),"#,##0") | G19: =TEXT('Price Basis'!C37,"#,##0")&" / "&TEXT('Price Basis'!C37*(1-Floor_Host),"#,##0")
A20: Enterprise | B20: ='Price Basis'!D30 | C20: =B20*(1-Floor_SW) | D20: ='Price Basis'!E30 | E20: =D20*(1-Floor_SW) | F20: =TEXT(ROUND('Price Basis'!G30*Blended/Round_To,0)*Round_To,"#,##0")&" / "&TEXT(ROUND('Price Basis'!G30*Blended/Round_To,0)*Round_To*(1-Floor_Svc),"#,##0") | G20: =TEXT('Price Basis'!C38,"#,##0")&" / "&TEXT('Price Basis'!C38*(1-Floor_Host),"#,##0")
A21: Per-user rates are the slab rates; the graduated slabs still apply at the floor (each slab rate less the floor discount).
A23: Give and get levers
A24: Lever | B24: What iorta TechNXT gets | C24: Allowed price effect | D24: Maximum | E24: Approver | F24: Counts toward the discount limit | G24: Conditions
A25: Longer term | B25: 3-year or 5-year committed subscription or AMC term, no termination for convenience in the term | C25: Off subscription fee | D25: 3 years: 3%; 5 years: 5% | E25: Account manager (3%); sales head (5%) | F25: Yes | G25: Early termination fee equal to the remaining committed fees of the term, or 50% of them if the owner prefers (decision).
A26: Upfront payment | B26: Subscription paid yearly in advance, or implementation 100% on signing | C26: Off the amount prepaid | D26: Subscription yearly in advance: 4%; implementation 100% on signing: 3% | E26: Account manager | F26: Yes | G26: Discount applies only to the prepaid period; lost if a payment is late more than 30 days.
A27: Reference customer | B27: Named as a client; two reference calls a year with prospects; logo use | C27: Off licence or subscription | D27: 2% | E27: Account manager | F27: Yes | G27: Signed reference clause in the Order Form; given after go-live.
A28: Case study | B28: Joint published case study within 6 months of go-live, with a quote from the sponsor | C28: Off licence or subscription, or a credit | D28: 2%, or PHP 100,000 credit against CRs | E28: Sales head | F28: Yes | G28: Credit used within 12 months; not paid out in cash.
A29: Multi-year AMC prepayment | B29: AMC for 3 years paid in advance at the start of the AMC term | C29: AMC for the prepaid years held at the first AMC year rate (no 5% escalation) | D29: About 5% of the prepaid AMC | E29: CEO | F29: No (AMC lever) | G29: Non-refundable except for iorta TechNXT breach; escalation resumes after the prepaid years.
A30: Reduced scope | B30: Fewer lines of business at go-live, broker loads its own data, remote training only | C30: Implementation fee falls by the man-days removed at the blended rate | D30: Up to the man-days removed (6 man-days per line of business) | E30: Account manager | F30: No (not a discount) | G30: Removed scope can be added later at the optional services price. Base man-days of the tier are not reduced.
A31: Phased users | B31: Contract for the full user count, delivered in tranches | C31: Licence or subscription billed per tranche; slab prices locked for 24 months | D31: Cash timing only | E31: Sales head | F31: No | G31: Subscription minimum billable users of the tier still apply. Perpetual tranches invoiced on activation.
A32: Signing date | B32: Order Form signed by a stated date (for example quarter end) | C32: Off licence or subscription | D32: 2% | E32: Sales head | F32: Yes | G32: Only with a dated written offer; lapses after the date.
A33: Onboarding reduction (subscription) | B33: 5-year subscription term | C33: Onboarding fee reduced to 90% of the implementation fee | D33: 10% off onboarding | E33: Sales head | F33: Yes | G33: The pricing workbook allows the onboarding percentage as a concession; the reduction is recovered in the term.
A35: Rules for every discount
A36: 1. Start at list price. Offer a lever (a get for a give) before any discretionary discount.
A37: 2. Each discount is shown as a separate line on the quotation and the Order Form, against the list price, with the lever named.
A38: 3. Record the approval (approver, date, reason) in the deal file before the quotation leaves iorta TechNXT. E-mail approval is enough.
A39: 4. Discounts apply to the initial term only unless the Order Form says otherwise. Added users are priced at list less the same discount in the initial term.
A40: 5. Hosting is priced from cloud cost; never discount it to win the software deal.
A41: 6. No side letters, free periods or unpriced extras. A free item is entered at list price with a 100% discount and counts toward the limit.
A42: 7. Quotations are valid 90 days. A re-issued quotation after expiry is repriced at the current price book.

Sheet Validity and Terms
A1: Validity and terms
A2: Read out or attach with every quotation. Applies to the Quick Quote and the pre-set packages.
A4: Quotation date | B4: ='Quick Quote'!$B$7
A5: Valid until | B5: ='Quick Quote'!$B$7+Validity
A7: Term | B7: Detail
A8: Validity | B8: =Validity&" days from the quotation date, for an Order Form signed in that period. Day rates are fixed for 12 months from signing."
A9: Currency | B9: ="Philippine peso (PHP). USD figures are for reference only at PHP "&TEXT(FX,"0.00")&" per USD ("&FX_Date&")."
A10: VAT | B10: All prices exclude 12% VAT, which is added on each invoice.
A11: Withholding tax | B11: A client that is a withholding agent deducts creditable withholding tax as its status and the payment type require and issues BIR Form 2307 for each deduction. Withholding does not reduce the invoice price. The treatment of the perpetual licence fee (sale of software or royalty) is confirmed by both parties' tax advisers before signing.
A12: Implementation or onboarding fee | B12: 40% on signing, 40% on UAT sign-off, 20% on go-live.
A13: Perpetual licence fee | B13: 100% on go-live.
A14: AMC | B14: 22% of the licence fee a year, yearly in advance from the AMC start year (Year 2, after a 12-month warranty from go-live). Increases 5% at each anniversary.
A15: Subscription | B15: Monthly in advance from go-live. Increases 5% at each contract anniversary. Minimum term 12 months; minimum billable users by tier.
A16: Hosting | B16: Monthly in advance from the date the environment is handed over. Cloud prices are estimates confirmed with the provider before a binding offer.
A17: Change requests | B17: Small: on delivery. Medium: 50% on approval, 50% on UAT sign-off. Large: 30% on approval, 50% on UAT sign-off, 20% on deployment.
A18: Optional services | B18: Monthly in arrears at actual days, or as quoted for fixed-price items. Travel outside Metro Manila at cost.
A19: Payment | B19: Invoices are payable within 30 days. Subscription and hosting may be suspended after 60 days of non-payment, with written notice.
A20: Scope | B20: iNXT BrokerVerse OOTB as delivered. Changes to the product are change requests at the published day rates.
A21: Contract | B21: Master Services Agreement with the Order Form and the schedules for the chosen model (licence or subscription, implementation SOW, support and SLA, hosting, data processing).

Sheet Price Basis
A1: Price basis: recommended price points
A2: From the pricing workbook. PHP, exclusive of VAT. Change only by rebuilding from the pricing workbook.
A4: General drivers
A5: Driver | B5: Value | C5: Unit | D5: Source
A6: Exchange rate (reference only) | B6: 62.75 | C6: PHP per USD | D6: Read from BrokerVerse_Commercials_and_Pricing.xlsx (recommended price points) when this book was built.
A7: Exchange rate date | B7: 25 Sep 2026 | C7: date
A8: VAT rate | B8: 0.12 | C8: %
A9: AMC rate (of perpetual licence fee) | B9: 0.22 | C9: % | D9: Read from BrokerVerse_Commercials_and_Pricing.xlsx (recommended price points) when this book was built.
A10: Annual escalation (AMC, subscription, 24x7 support) | B10: 0.05 | C10: %
A11: AMC starts in contract year | B11: 2 | C11: year
A12: Subscription onboarding fee as % of implementation fee | B12: 1 | C12: %
A13: Infrastructure annual change | B13: 0 | C13: %
A14: Extra implementation man-days per line of business above the included count | B14: 6 | C14: man-days
A15: Rounding of implementation fees | B15: 10000 | C15: PHP
A16: Quotation validity | B16: 90 | C16: days
A17: Blended day rate | B17: 16100 | C17: PHP per man-day
A18: Business analyst day rate | B18: 18000 | C18: PHP per man-day
A19: Developer day rate | B19: 16000 | C19: PHP per man-day
A20: QA engineer day rate | B20: 12000 | C20: PHP per man-day
A21: Project manager day rate | B21: 22000 | C21: PHP per man-day
... A23: On-site consultant day (Metro Manila) | B23: 20000 | C23: PHP per day
A25: Size tiers, graduated user slabs and tier parameters
A26: Tier | B26: From users | C26: To users | D26: Perpetual licence per user, slab (PHP) | E26: Subscription per user per month, slab (PHP) | F26: Minimum billable users (subscription) | G26: Implementation base man-days | H26: Lines of business included | I26: Training days included | J26: Reference users | K26: 24x7 Severity 1 support per year (PHP) | L26: Implementation duration (Implementation Approach)
A27: Small | B27: 1 | C27: 25 | D27: 90000 | E27: 3200 | F27: 10 | G27: 70 | H27: 5 | I27: 4 | J27: 15 | K27: 240000 | L27: 8 weeks
A28: Medium | B28: 26 | C28: 100 | D28: 78000 | E28: 2800 | F28: 26 | G28: 130 | H28: 8 | I28: 6 | J28: 60 | K28: 480000 | L28: 12 weeks
A29: Large | B29: 101 | C29: 300 | D29: 66000 | E29: 2400 | F29: 101 | G29: 230 | H29: 12 | I29: 10 | J29: 180 | K29: 900000 | L29: 16 to 20 weeks
A30: Enterprise | B30: 301 | C30: 100000 | D30: 54000 | E30: 2000 | F30: 301 | G30: 360 | H30: 16 | I30: 15 | J30: 400 | K30: 1500000 | L30: 20 weeks or more, planned at mobilisation
A31: Graduated slabs: the first 25 users are charged at the Small rate, users 26 to 100 at the Medium rate, users 101 to 300 at the Large rate and the rest at the Enterprise rate. The tier, set by the total user count, decides the implementation effort, the minimum billable users for subscription, the training days included and the hosting size.
A33: Hosting per month (production plus one UAT environment, PHP)
A34: Tier | B34: Self-hosted | C34: AWS | D34: Azure | E34: Local partner
A35: Small | B35: 0 | C35: 30000 | D35: 31000 | E35: 28000
A36: Medium | B36: 0 | C36: 62000 | D36: 65000 | E36: 59000
A37: Large | B37: 0 | C37: 112000 | D37: 118000 | E37: 107000
A38: Enterprise | B38: 0 | C38: 244000 | D38: 256000 | E38: 232000
A39: Self-hosted: the client hosts in its own cloud account or data centre; no hosting fee, deployment guide supplied, set-up support at day rates. AWS and Azure are priced on their Singapore regions; the local partner option keeps data in the Philippines. Cloud prices are estimates to be confirmed with the provider before a binding offer.
A41: Optional services (PHP)
A42: Item | B42: Price | C42: Unit
A43: Additional environment, set-up | B43: 100000 | C43: one-time
A44: Additional environment hosted by iorta TechNXT | B44: 11000 | C44: per month
A45: Data migration beyond the standard templates | B45: 240000 | C45: per legacy source
...
