Workbook
Name PackNames: Packages!$A$5:$A$21
Name PackCosts: Packages!$B$5:$F$21
Name Pack: Inputs!$B$6
Name Comm_Income: Inputs!$B$7
Name Growth: Inputs!$B$8
Name V_Policy: Inputs!$B$11
Name V_Renew: Inputs!$B$12
Name V_Endt: Inputs!$B$13
Name V_Claim: Inputs!$B$14
Name V_OR: Inputs!$B$15
Name V_Remit: Inputs!$B$16
Name V_Bank: Inputs!$B$17
Name Staff_Cost: Inputs!$B$20
Name Hours_Month: Inputs!$B$21
Name Hour_Cost: Inputs!$B$22
Name Cash_Share: Inputs!$B$23
Name Err_Rate: Inputs!$B$38
Name Err_Hours: Inputs!$B$39
Name Err_Red: Inputs!$B$40
Name Late_Charges: Inputs!$B$43
Name Late_Red: Inputs!$B$44
Name Comm_Delay: Inputs!$B$45
Name Comm_Delay_Red: Inputs!$B$46
Name Cost_Money: Inputs!$B$47
Name Leak_Rate: Inputs!$B$48
Name Leak_Red: Inputs!$B$49
Name Renew_Share: Inputs!$B$52
Name Ret_Now: Inputs!$B$53
Name Ret_Gain: Inputs!$B$54
Name Legacy: Inputs!$B$57
Name Real_Y1: Inputs!$B$60
Name Real_Y2: Inputs!$B$61
Name Real_Y3: Inputs!$B$62
Name Disc_Rate: Inputs!$B$63

Sheet Read Me
A1: iNXT BrokerVerse OOTB: ROI calculator
A2: iorta TechNXT Corp. Prepared 03 October 2026. PHP, exclusive of VAT. Example figures only: replace them with the broker's own.
A4: Topic | B4: Notes
A5: Purpose | B5: Estimates the yearly benefit of iNXT BrokerVerse OOTB for a broker (staff hours saved, rework avoided, remittance and commission cash effects, renewal retention) and compares it with the cost of a chosen package to give the payback period, the 5-year net benefit and the return.
A6: How to use | B6: 1. On Inputs, replace every yellow cell with the broker's figures. Each input has a label, a unit and its basis. 2. Pick the package (pre-set packages at list price from the price book), or choose "Custom" and type the yearly costs of a quotation. 3. Read Results. Recalculate (F9) if your spreadsheet tool does not recalculate on open.
A7: Status of the defaults | B7: The default inputs describe a fictitious medium broker (60 users). Time per task, error rates, improvement rates and money figures are assumptions for illustration, not measured results of BrokerVerse. Cells with a light orange basis are assumptions that the broker must confirm, ideally from a short time study of the current process.
A8: Method | B8: Hours saved = volume x current time per item x expected reduction. Cost saved = hours saved x hourly staff cost x the share of hours that turns into cash (avoided hiring, overtime or temporary staff). Rework, remittance charges, commission cash timing, commission leakage and renewal retention are added as separate lines. Year 1 counts only part of the benefit (go-live during the year and learning); volumes grow each year.
A9: Package costs | B9: Package costs are the list prices of the pre-set packages in iNXT_BrokerVerse_Price_Book.xlsx for the tier reference user counts, copied as values when this workbook was built, by contract year from go-live (implementation and licence in Year 1). For any other configuration, use Custom with the Quick Quote figures.
A10: Colour key | B10: Yellow cell with blue text: input. Light orange: assumption to confirm. Green: result.

Sheet Inputs
A1: Inputs: all assumptions are editable
A2: Yellow cells are inputs. Replace the example figures with the broker's own. Light orange basis = assumption to confirm.
A4: Package and broker profile
A5: Input | B5: Value | C5: Unit | D5: Basis
A6: Package to compare against | B6: Medium: Standard (subscription, AWS) | C6: list | D6: Pick a pre-set package or "Custom" (Packages sheet).
A7: Commission income per year | B7: 120000000 | C7: PHP | D7: Example: medium broker estimate used in the pricing workbook (IC 2024 rank about 10 to 30).
A8: Business volume growth per year | B8: 0.05 | C8: % a year | D8: Assumption. Applied to volumes and money benefits from Year 2.
A9: Volumes per year
A10: Input | B10: Value | C10: Unit | D10: Basis
A11: New policies issued | B11: 12000 | C11: items a year | D11: Example. Take from the current system or registers for the last 12 months.
A12: Renewals processed | B12: 8000 | C12: items a year | D12: Example. Take from the current system or registers for the last 12 months.
A13: Endorsements | B13: 3000 | C13: items a year | D13: Example. Take from the current system or registers for the last 12 months.
A14: Claims notified and followed up | B14: 1500 | C14: items a year | D14: Example. Take from the current system or registers for the last 12 months.
A15: Official receipts and collections posted | B15: 20000 | C15: items a year | D15: Example. Take from the current system or registers for the last 12 months.
A16: Insurer remittance batches per month | B16: 40 | C16: batches a month | D16: Example: number of insurers x remittances per insurer per month.
A17: Bank accounts reconciled each month | B17: 6 | C17: accounts | D17: Example.
A18: Staff cost
A19: Input | B19: Value | C19: Unit | D19: Basis
A20: Fully loaded monthly cost of an operations or accounting staff member | B20: 40000 | C20: PHP a month | D20: Assumption: salary, 13th month pay, statutory contributions and benefits. Use the broker's payroll average.
A21: Working hours per staff member per month | B21: 176 | C21: hours | D21: Assumption: 22 days x 8 hours.
A22: Hourly staff cost | B22: =Staff_Cost/Hours_Month | C22: PHP an hour
A23: Share of hours saved that becomes a cost saving | B23: 0.6 | C23: % | D23: Assumption: avoided hiring, overtime and temporary staff. The rest is capacity for growth and service, not counted as cash.
A24: Time on manual tasks today and expected reduction
A25: Task | B25: Minutes per item today | C25: Expected reduction | D25: Basis
A26: Quotation, placement and policy issuance (per new policy) | B26: 60 | C26: 0.4 | D26: Assumption. Quotation, placement slip, policy and billing in one flow; product templates and motor tariff compute premium and taxes.
A27: Renewal processing (per renewal) | B27: 45 | C27: 0.5 | D27: Assumption. Renewal lists and notices from expiring policies instead of manual tracking.
A28: Endorsement (per endorsement) | B28: 30 | C28: 0.35 | D28: Assumption. Endorsement on the policy record with automatic premium and tax lines.
A29: Claim notification and follow-up (per claim) | B29: 90 | C29: 0.25 | D29: Assumption. Claim record, documents and status in one place.
A30: Official receipt and collection posting (per receipt) | B30: 10 | C30: 0.5 | D30: Assumption. Receipt against open items with automatic journal from posting rules.
A31: Remittance preparation and approval (per batch) | B31: 180 | C31: 0.6 | D31: Assumption. Remittance built from collected premiums by insurer, with approval and ageing.
A32: Bank reconciliation (per account per month) | B32: 960 | C32: 0.6 | D32: Assumption. Bank statement import and matching instead of manual ticking.
A33: Month-end close and BIR working papers (per month) | B33: 4800 | C33: 0.5 | D33: Assumption. Month-End Close run and BIR working papers (2307, VAT Summary, SAWT, QAP, SLSP) from posted data.
A34: Commission computation and statements (per month) | B34: 2400 | C34: 0.6 | D34: Assumption. Commission from rate matrix and referrer sharing; statements from the system.
D35: Month-based tasks: minutes per month (4,800 minutes = 80 hours). Reductions are planning assumptions, to be confirmed by a time study.
A36: Errors and rework
A37: Input | B37: Value | C37: Unit | D37: Basis
A38: Transactions with an error that needs rework today (policies, endorsements, receipts) | B38: 0.04 | C38: % of transactions | D38: Assumption: wrong premium, tax, commission, client or insurer detail.
A39: Hours to find and correct one error | B39: 1.5 | C39: hours | D39: Assumption: includes reversal, re-issue and communication.
A40: Expected reduction in errors | B40: 0.5 | C40: % | D40: Assumption: validations, computed taxes, maker-checker approvals.
A41: Remittance and commission cash
...

Sheet Results
A1: Results
A2: PHP, exclusive of VAT. Formula driven from Inputs and Packages.
A4: Hours saved by task (full year)
A5: Task | B5: Items a year | C5: Hours a year today | D5: Reduction | E5: Hours saved a year | F5: Cost of hours saved (PHP) | G5: Cash saving (PHP)
A6: =Inputs!A26 | B6: =V_Policy*1 | C6: =B6*Inputs!B26/60 | D6: =Inputs!C26 | E6: =C6*D6 | F6: =E6*Hour_Cost | G6: =F6*Cash_Share
A7: =Inputs!A27 | B7: =V_Renew*1 | C7: =B7*Inputs!B27/60 | D7: =Inputs!C27 | E7: =C7*D7 | F7: =E7*Hour_Cost | G7: =F7*Cash_Share
A8: =Inputs!A28 | B8: =V_Endt*1 | C8: =B8*Inputs!B28/60 | D8: =Inputs!C28 | E8: =C8*D8 | F8: =E8*Hour_Cost | G8: =F8*Cash_Share
A9: =Inputs!A29 | B9: =V_Claim*1 | C9: =B9*Inputs!B29/60 | D9: =Inputs!C29 | E9: =C9*D9 | F9: =E9*Hour_Cost | G9: =F9*Cash_Share
A10: =Inputs!A30 | B10: =V_OR*1 | C10: =B10*Inputs!B30/60 | D10: =Inputs!C30 | E10: =C10*D10 | F10: =E10*Hour_Cost | G10: =F10*Cash_Share
A11: =Inputs!A31 | B11: =V_Remit*12 | C11: =B11*Inputs!B31/60 | D11: =Inputs!C31 | E11: =C11*D11 | F11: =E11*Hour_Cost | G11: =F11*Cash_Share
A12: =Inputs!A32 | B12: =V_Bank*12 | C12: =B12*Inputs!B32/60 | D12: =Inputs!C32 | E12: =C12*D12 | F12: =E12*Hour_Cost | G12: =F12*Cash_Share
A13: =Inputs!A33 | B13: =12 | C13: =B13*Inputs!B33/60 | D13: =Inputs!C33 | E13: =C13*D13 | F13: =E13*Hour_Cost | G13: =F13*Cash_Share
A14: =Inputs!A34 | B14: =12 | C14: =B14*Inputs!B34/60 | D14: =Inputs!C34 | E14: =C14*D14 | F14: =E14*Hour_Cost | G14: =F14*Cash_Share
A15: Total | C15: =SUM(C6:C14) | E15: =SUM(E6:E14) | F15: =SUM(F6:F14) | G15: =SUM(G6:G14)
A16: Full-time equivalents released (hours saved / yearly hours of one person) | E16: =E15/(Hours_Month*12)
A18: Yearly benefit at full run rate
A19: Benefit | B19: PHP a year | C19: How it is computed
A20: Staff time saved (cash share) | B20: =G15 | C20: Hours saved x hourly cost x share that becomes a cost saving.
A21: Rework avoided | B21: =(V_Policy+V_Renew+V_Endt+V_OR)*Err_Rate*Err_Red*Err_Hours*Hour_Cost | C21: Transactions x error rate x reduction x hours per error x hourly cost.
A22: Late remittance charges avoided | B22: =Late_Charges*Late_Red | C22: Charges today x expected reduction.
A23: Commission collected earlier (cost of money) | B23: =Comm_Income*Comm_Delay_Red/365*Cost_Money | C23: Commission income x days gained / 365 x cost of money.
A24: Commission leakage recovered | B24: =Comm_Income*Leak_Rate*Leak_Red | C24: Commission income x leakage rate x recovery.
A25: Renewal retention gain | B25: =Comm_Income*Renew_Share*Ret_Gain | C25: Renewable commission x improvement in retention (percentage points).
A26: Current system costs avoided | B26: =Legacy | C26: As entered.
A27: Total yearly benefit at full run rate | B27: =SUM(B20:B26)
A28: Benefit as a share of commission income | B28: =B27/Comm_Income
A30: Benefit against the cost of the selected package
A31: Selected package | B31: =Pack
A32: Line | B32: Year 1 | C32: Year 2 | D32: Year 3 | E32: Year 4 | F32: Year 5 | G32: 5-year total
A33: Share of full benefit realised | B33: =Real_Y1 | C33: =Real_Y2 | D33: =Real_Y3 | E33: =Real_Y3 | F33: =Real_Y3
A34: Volume growth factor | B34: =(1+Growth)^(1-1) | C34: =(1+Growth)^(2-1) | D34: =(1+Growth)^(3-1) | E34: =(1+Growth)^(4-1) | F34: =(1+Growth)^(5-1)
A35: Benefit | B35: =$B$27*B33*B34 | C35: =$B$27*C33*C34 | D35: =$B$27*D33*D34 | E35: =$B$27*E33*E34 | F35: =$B$27*F33*F34 | G35: =SUM(B35:F35)
A36: Package cost | B36: =INDEX(PackCosts,MATCH(Pack,PackNames,0),1) | C36: =INDEX(PackCosts,MATCH(Pack,PackNames,0),2) | D36: =INDEX(PackCosts,MATCH(Pack,PackNames,0),3) | E36: =INDEX(PackCosts,MATCH(Pack,PackNames,0),4) | F36: =INDEX(PackCosts,MATCH(Pack,PackNames,0),5) | G36: =SUM(B36:F36)
A37: Net benefit | B37: =B35-B36 | C37: =C35-C36 | D37: =D35-D36 | E37: =E35-E36 | F37: =F35-F36 | G37: =SUM(B37:F37)
A38: Cumulative net benefit | B38: =0+B37 | C38: =B38+C37 | D38: =C38+D37 | E38: =D38+E37 | F38: =E38+F37
A39: Payback helper (months) | B39: =IF(AND(0<0,B38>=0),(1-1)*12+12*(-0)/B37,IF(AND(1=1,B38>=0),12*B36/B35,"")) | C39: =IF(AND(B38<0,C38>=0),(2-1)*12+12*(-B38)/C37,IF(AND(2=1,C38>=0),12*C36/C35,"")) | D39: =IF(AND(C38<0,D38>=0),(3-1)*12+12*(-C38)/D37,IF(AND(3=1,D38>=0),12*D36/D35,"")) | E39: =IF(AND(D38<0,E38>=0),(4-1)*12+12*(-D38)/E37,IF(AND(4=1,E38>=0),12*E36/E35,"")) | F39: =IF(AND(E38<0,F38>=0),(5-1)*12+12*(-E38)/F37,IF(AND(5=1,F38>=0),12*F36/F35,""))
A41: Summary
A42: Hours saved a year at full run rate | B42: =E15
A43: Full-time equivalents released | B43: =E15/(Hours_Month*12)
A44: Cost saved a year at full run rate (staff time and rework) | B44: =B20+B21
...

Sheet Packages
A1: Package costs by contract year (PHP, excl. VAT, list price)
A2: From the Pre-set Packages sheet of the price book. Custom: type the yearly costs of a specific quotation (Quick Quote, year by year table).
A4: Package | B4: Year 1 | C4: Year 2 | D4: Year 3 | E4: Year 4 | F4: Year 5 | G4: 5-year total
A5: Small: Essentials (subscription, Self-hosted) | B5: 1706000 | C5: 604800 | D5: 635040 | E5: 666792 | F5: 700131.6 | G5: =SUM(B5:F5)
A6: Small: Standard (subscription, AWS) | B6: 2264000 | C6: 1141800 | D6: 1172040 | E6: 1203792 | F6: 1237131.6 | G6: =SUM(B6:F6)
A7: Small: Ownership (perpetual, AWS) | B7: 3038000 | C7: 834000 | D7: 848850 | E7: 864442.5 | F7: 880814.62 | G7: =SUM(B7:F7)
A8: Small: Ownership Plus (perpetual, Local partner) | B8: 3564000 | C8: 1073000 | D8: 1100450 | E8: 1129272.5 | F8: 1159536.1 | G8: =SUM(B8:F8)
A9: Medium: Essentials (subscription, Self-hosted) | B9: 4226000 | C9: 2242800 | D9: 2354940 | E9: 2472687 | F9: 2596321.4 | G9: =SUM(B9:F9)
A10: Medium: Standard (subscription, AWS) | B10: 5148000 | C10: 3117800 | D10: 3229940 | E10: 3347687 | F10: 3471321.4 | G10: =SUM(B10:F10)
A11: Medium: Ownership (perpetual, AWS) | B11: 7992000 | C11: 1970600 | D11: 2025380 | E11: 2082899 | F11: 2143294 | G11: =SUM(B11:F11)
A12: Medium: Ownership Plus (perpetual, Local partner) | B12: 8744000 | C12: 2448600 | D12: 2528580 | E12: 2612559 | F12: 2700737 | G12: =SUM(B12:F12)
A13: Large: Essentials (subscription, Self-hosted) | B13: 9484000 | C13: 6073200 | D13: 6376860 | E13: 6695703 | F13: 7030488.2 | G13: =SUM(B13:F13)
A14: Large: Standard (subscription, AWS) | B14: 11372000 | C14: 7875200 | D14: 8178860 | E14: 8497703 | F14: 8832488.2 | G14: =SUM(B14:F14)
A15: Large: Ownership (perpetual, AWS) | B15: 18968000 | C15: 4745600 | D15: 4892780 | E15: 5047319 | F15: 5209585 | G15: =SUM(B15:F15)
A16: Large: Ownership Plus (perpetual, Local partner) | B16: 20064000 | C16: 5590600 | D16: 5785030 | E16: 5989181.5 | F16: 6203540.6 | G16: =SUM(B16:F16)
... A21: Custom | B21: 4970000 | C21: 2986800 | D21: 3098940 | E21: 3216687 | F21: 3340321 | G21: =SUM(B21:F21)
