Workbook

Sheet Instructions
A1: BrokerVerse OOTB: Discovery and Configuration Workbook
A3: Purpose | B3: Records every configuration decision of the broker during mobilisation and the discovery workshops. It is the configuration workbook named in the Implementation Approach and Plan and is signed off at the end of discovery.
A4: How to use | B4: One sheet per area. Each row is a question or a configuration item, the BrokerVerse screen where it is set, and the value delivered out of the box. The broker writes its decision in Client answer (yellow). Leave Client answer empty to keep the OOTB default and set Status to Confirmed.
A5: Columns | B5: ID; Topic; Question or configuration item; BrokerVerse screen (menu path as on screen); OOTB default (seeded value); Client answer; Owner (broker role that answers); Needed by (project phase); Due date (set at kick-off); Status; Notes and setting key (technical key on Master > Configuration, upload template or reference document).
A6: Status values | B6: Open: not yet answered. Answered: broker answer recorded. Confirmed: reviewed in the workshop by the owner and iorta TechNXT. Configured: entered in the test environment and checked. Not applicable: area not used. Gap (CR): cannot be met by configuration; recorded in the fit-gap register as a change request.
A7: Needed by | B7: Mobilisation (week 1), Discovery (workshops), Configuration, Mock load 1, UAT. Due dates follow the plan of the implementation size.
A8: Defaults | B8: OOTB defaults are the values seeded in the delivered system on 03 October 2026. Money in PHP. Tax rates, ATC and GL accounts are confirmed by the broker's accountant and tax adviser before configuration.
A9: Rules | B9: Do not change the layout of the sheets. Add rows at the end of a sheet with the next ID if a new item comes up. Personal data (staff lists, client extracts) is not pasted into this workbook; it goes into the upload templates.
A10: Companion | B10: Discovery Workbook Guide (how to run the workshops); Implementation Approach and Plan; Data Migration and Cutover Plan; upload templates in docs/templates.

Sheet Summary
A1: Sheet | B1: Items | C1: Open | D1: Answered | E1: Confirmed | F1: Configured | G1: Not applicable | H1: Gap (CR) | I1: Percent configured
A2: Company and Branches | B2: =COUNTA('Company and Branches'!$A$2:$A$1000) | C2: =COUNTIF('Company and Branches'!$J$2:$J$1000,"Open") | D2: =COUNTIF('Company and Branches'!$J$2:$J$1000,"Answered") | E2: =COUNTIF('Company and Branches'!$J$2:$J$1000,"Confirmed") | F2: =COUNTIF('Company and Branches'!$J$2:$J$1000,"Configured") | G2: =COUNTIF('Company and Branches'!$J$2:$J$1000,"Not applicable") | H2: =COUNTIF('Company and Branches'!$J$2:$J$1000,"Gap (CR)") | I2: =IF(B2=0,0,(F2+G2)/B2)
A3: Users and Roles | B3: =COUNTA('Users and Roles'!$A$2:$A$1000) | C3: =COUNTIF('Users and Roles'!$J$2:$J$1000,"Open") | D3: =COUNTIF('Users and Roles'!$J$2:$J$1000,"Answered") | E3: =COUNTIF('Users and Roles'!$J$2:$J$1000,"Confirmed") | F3: =COUNTIF('Users and Roles'!$J$2:$J$1000,"Configured") | G3: =COUNTIF('Users and Roles'!$J$2:$J$1000,"Not applicable") | H3: =COUNTIF('Users and Roles'!$J$2:$J$1000,"Gap (CR)") | I3: =IF(B3=0,0,(F3+G3)/B3)
A4: Insurers | B4: =COUNTA('Insurers'!$A$2:$A$1000) | C4: =COUNTIF('Insurers'!$J$2:$J$1000,"Open") | D4: =COUNTIF('Insurers'!$J$2:$J$1000,"Answered") | E4: =COUNTIF('Insurers'!$J$2:$J$1000,"Confirmed") | F4: =COUNTIF('Insurers'!$J$2:$J$1000,"Configured") | G4: =COUNTIF('Insurers'!$J$2:$J$1000,"Not applicable") | H4: =COUNTIF('Insurers'!$J$2:$J$1000,"Gap (CR)") | I4: =IF(B4=0,0,(F4+G4)/B4)
A5: Products and LOB | B5: =COUNTA('Products and LOB'!$A$2:$A$1000) | C5: =COUNTIF('Products and LOB'!$J$2:$J$1000,"Open") | D5: =COUNTIF('Products and LOB'!$J$2:$J$1000,"Answered") | E5: =COUNTIF('Products and LOB'!$J$2:$J$1000,"Confirmed") | F5: =COUNTIF('Products and LOB'!$J$2:$J$1000,"Configured") | G5: =COUNTIF('Products and LOB'!$J$2:$J$1000,"Not applicable") | H5: =COUNTIF('Products and LOB'!$J$2:$J$1000,"Gap (CR)") | I5: =IF(B5=0,0,(F5+G5)/B5)
A6: Commission Rates | B6: =COUNTA('Commission Rates'!$A$2:$A$1000) | C6: =COUNTIF('Commission Rates'!$J$2:$J$1000,"Open") | D6: =COUNTIF('Commission Rates'!$J$2:$J$1000,"Answered") | E6: =COUNTIF('Commission Rates'!$J$2:$J$1000,"Confirmed") | F6: =COUNTIF('Commission Rates'!$J$2:$J$1000,"Configured") | G6: =COUNTIF('Commission Rates'!$J$2:$J$1000,"Not applicable") | H6: =COUNTIF('Commission Rates'!$J$2:$J$1000,"Gap (CR)") | I6: =IF(B6=0,0,(F6+G6)/B6)
A7: Chart of Accounts | B7: =COUNTA('Chart of Accounts'!$A$2:$A$1000) | C7: =COUNTIF('Chart of Accounts'!$J$2:$J$1000,"Open") | D7: =COUNTIF('Chart of Accounts'!$J$2:$J$1000,"Answered") | E7: =COUNTIF('Chart of Accounts'!$J$2:$J$1000,"Confirmed") | F7: =COUNTIF('Chart of Accounts'!$J$2:$J$1000,"Configured") | G7: =COUNTIF('Chart of Accounts'!$J$2:$J$1000,"Not applicable") | H7: =COUNTIF('Chart of Accounts'!$J$2:$J$1000,"Gap (CR)") | I7: =IF(B7=0,0,(F7+G7)/B7)
A8: Banks and Gateways | B8: =COUNTA('Banks and Gateways'!$A$2:$A$1000) | C8: =COUNTIF('Banks and Gateways'!$J$2:$J$1000,"Open") | D8: =COUNTIF('Banks and Gateways'!$J$2:$J$1000,"Answered") | E8: =COUNTIF('Banks and Gateways'!$J$2:$J$1000,"Confirmed") | F8: =COUNTIF('Banks and Gateways'!$J$2:$J$1000,"Configured") | G8: =COUNTIF('Banks and Gateways'!$J$2:$J$1000,"Not applicable") | H8: =COUNTIF('Banks and Gateways'!$J$2:$J$1000,"Gap (CR)") | I8: =IF(B8=0,0,(F8+G8)/B8)
A9: Numbering Series | B9: =COUNTA('Numbering Series'!$A$2:$A$1000) | C9: =COUNTIF('Numbering Series'!$J$2:$J$1000,"Open") | D9: =COUNTIF('Numbering Series'!$J$2:$J$1000,"Answered") | E9: =COUNTIF('Numbering Series'!$J$2:$J$1000,"Confirmed") | F9: =COUNTIF('Numbering Series'!$J$2:$J$1000,"Configured") | G9: =COUNTIF('Numbering Series'!$J$2:$J$1000,"Not applicable") | H9: =COUNTIF('Numbering Series'!$J$2:$J$1000,"Gap (CR)") | I9: =IF(B9=0,0,(F9+G9)/B9)
A10: Approvals and Limits | B10: =COUNTA('Approvals and Limits'!$A$2:$A$1000) | C10: =COUNTIF('Approvals and Limits'!$J$2:$J$1000,"Open") | D10: =COUNTIF('Approvals and Limits'!$J$2:$J$1000,"Answered") | E10: =COUNTIF('Approvals and Limits'!$J$2:$J$1000,"Confirmed") | F10: =COUNTIF('Approvals and Limits'!$J$2:$J$1000,"Configured") | G10: =COUNTIF('Approvals and Limits'!$J$2:$J$1000,"Not applicable") | H10: =COUNTIF('Approvals and Limits'!$J$2:$J$1000,"Gap (CR)") | I10: =IF(B10=0,0,(F10+G10)/B10)
A11: E-mail and Templates | B11: =COUNTA('E-mail and Templates'!$A$2:$A$1000) | C11: =COUNTIF('E-mail and Templates'!$J$2:$J$1000,"Open") | D11: =COUNTIF('E-mail and Templates'!$J$2:$J$1000,"Answered") | E11: =COUNTIF('E-mail and Templates'!$J$2:$J$1000,"Confirmed") | F11: =COUNTIF('E-mail and Templates'!$J$2:$J$1000,"Configured") | G11: =COUNTIF('E-mail and Templates'!$J$2:$J$1000,"Not applicable") | H11: =COUNTIF('E-mail and Templates'!$J$2:$J$1000,"Gap (CR)") | I11: =IF(B11=0,0,(F11+G11)/B11)
A12: Taxes and LGU | B12: =COUNTA('Taxes and LGU'!$A$2:$A$1000) | C12: =COUNTIF('Taxes and LGU'!$J$2:$J$1000,"Open") | D12: =COUNTIF('Taxes and LGU'!$J$2:$J$1000,"Answered") | E12: =COUNTIF('Taxes and LGU'!$J$2:$J$1000,"Confirmed") | F12: =COUNTIF('Taxes and LGU'!$J$2:$J$1000,"Configured") | G12: =COUNTIF('Taxes and LGU'!$J$2:$J$1000,"Not applicable") | H12: =COUNTIF('Taxes and LGU'!$J$2:$J$1000,"Gap (CR)") | I12: =IF(B12=0,0,(F12+G12)/B12)
A13: Data Migration Sources | B13: =COUNTA('Data Migration Sources'!$A$2:$A$1000) | C13: =COUNTIF('Data Migration Sources'!$J$2:$J$1000,"Open") | D13: =COUNTIF('Data Migration Sources'!$J$2:$J$1000,"Answered") | E13: =COUNTIF('Data Migration Sources'!$J$2:$J$1000,"Confirmed") | F13: =COUNTIF('Data Migration Sources'!$J$2:$J$1000,"Configured") | G13: =COUNTIF('Data Migration Sources'!$J$2:$J$1000,"Not applicable") | H13: =COUNTIF('Data Migration Sources'!$J$2:$J$1000,"Gap (CR)") | I13: =IF(B13=0,0,(F13+G13)/B13)
A14: Integrations | B14: =COUNTA('Integrations'!$A$2:$A$1000) | C14: =COUNTIF('Integrations'!$J$2:$J$1000,"Open") | D14: =COUNTIF('Integrations'!$J$2:$J$1000,"Answered") | E14: =COUNTIF('Integrations'!$J$2:$J$1000,"Confirmed") | F14: =COUNTIF('Integrations'!$J$2:$J$1000,"Configured") | G14: =COUNTIF('Integrations'!$J$2:$J$1000,"Not applicable") | H14: =COUNTIF('Integrations'!$J$2:$J$1000,"Gap (CR)") | I14: =IF(B14=0,0,(F14+G14)/B14)
A15: Reports | B15: =COUNTA('Reports'!$A$2:$A$1000) | C15: =COUNTIF('Reports'!$J$2:$J$1000,"Open") | D15: =COUNTIF('Reports'!$J$2:$J$1000,"Answered") | E15: =COUNTIF('Reports'!$J$2:$J$1000,"Confirmed") | F15: =COUNTIF('Reports'!$J$2:$J$1000,"Configured") | G15: =COUNTIF('Reports'!$J$2:$J$1000,"Not applicable") | H15: =COUNTIF('Reports'!$J$2:$J$1000,"Gap (CR)") | I15: =IF(B15=0,0,(F15+G15)/B15)
A16: Total | B16: =SUM(B2:B15) | C16: =SUM(C2:C15) | D16: =SUM(D2:D15) | E16: =SUM(E2:E15) | F16: =SUM(F2:F15) | G16: =SUM(G2:G15) | H16: =SUM(H2:H15) | I16: =IF(B16=0,0,(F16+G16)/B16)

Sheet Company and Branches
A1: ID | B1: Topic | C1: Question or configuration item | D1: BrokerVerse screen | E1: OOTB default | F1: Client answer | G1: Owner (broker) | H1: Needed by | I1: Due date | J1: Status | K1: Notes and setting key
A2: CO-01 | B2: Legal identity | C2: Registered company name exactly as on the SEC and BIR registration | D2: Master > Generals > Organization > Company | E2: Seeded company ITX "iorta TechNXT Corp.": replace | G2: Sponsor | H2: Mobilisation | J2: Open | K2: Primary company is the letterhead on documents and BIR forms
A3: CO-02 | B3: Legal identity | C3: TIN and RDO code | D3: Master > Generals > Organization > Company | E3: Blank | G3: Accounting Manager | H3: Mobilisation | J3: Open | K3: Fields TIN, RDO Code
A4: CO-03 | B4: Legal identity | C4: Registered address, ZIP code, city, province | D4: Master > Generals > Organization > Company | E4: Blank | G4: Accounting Manager | H4: Mobilisation | J4: Open | K4: Fields Address Line 1 to 3, Pin Code, City, State
A5: CO-04 | B5: Legal identity | C5: Insurance Commission certificate of authority (licence) number and validity | D5: Master > Generals > Organization > Company | E5: Blank | G5: Sponsor | H5: Mobilisation | J5: Open | K5: Field License Number
A6: CO-05 | B6: Legal identity | C6: Company e-mail, telephone, website | D6: Master > Generals > Organization > Company | E6: Blank | G6: System Administrator | H6: Configuration | J6: Open
A7: CO-06 | B7: Legal identity | C7: More than one legal entity on the system? Which one is the letterhead company | D7: Master > Generals > Organization > Company | E7: One company | G7: Sponsor | H7: Discovery | J7: Open | K7: Field "Letterhead company - used on documents and reports"
A8: CO-07 | B8: Branding | C8: Logo for printed documents (PNG, at least 300 px wide) | D8: Master > Generals > Organization > Company | E8: iorta TechNXT logo (fallback) | G8: System Administrator | H8: Configuration | J8: Open | K8: documents.default_logo_path is the fallback only
A9: CO-08 | B9: Branding | C9: Application name on the sign-in page, side bar and browser tab | D9: Master > System Settings | E9: BrokerVerse | G9: Sponsor | H9: Configuration | J9: Open | K9: general.system_name
A10: CO-09 | B10: Branding | C10: Screen logo and colours | D10: Master > System Settings | E10: Primary #0072d8, secondary #004ea8 | G10: System Administrator | H10: Configuration | J10: Open | K10: branding.logo_url, branding.primary_color, branding.secondary_color
A11: CO-10 | B11: Branding | C11: Accent colour of printed documents and report PDFs | D11: Master > Configuration (Company & Branding) | E11: #1f4e79 | G11: System Administrator | H11: Configuration | J11: Open | K11: documents.accent_color
A12: CO-11 | B12: Branches | C12: List of branches: code, name, address, e-mail, telephone | D12: Master > Generals > Organization > Branch | E12: HO Head Office, Makati City | G12: Operations head | H12: Mock load 1 | J12: Open | K12: Branch_Upload_Template.xlsx
A13: CO-12 | B13: Branches | C13: Departments per branch | D13: Master > Generals > Organization > Branch (Department_Upload_Template.xlsx) | E13: Seeded departments | G13: Operations head | H13: Mock load 1 | J13: Open | K13: Department upload through the API route written on the template
A14: CO-13 | B14: People | C14: Employee hierarchy (ranks) and designations | D14: Master > Generals > Employee Management > Hierarchy; Designation | E14: Seeded hierarchy and designations | G14: HR | H14: Mock load 1 | J14: Open | K14: Hierarchy_ and Designation_Upload_Template.xlsx
A15: CO-14 | B15: People | C15: Employees and sales persons with branch, department, reporting line | D15: Master > Generals > Employee Management > Employee | E15: None | G15: HR | H15: Mock load 1 | J15: Open | K15: Employee codes EMP-0001 (series employee)
A16: CO-15 | B16: Calendar | C16: Fiscal year start month | D16: Master > Configuration (Accounting & Tax) | E16: 1 (January) | G16: Accounting Manager | H16: Discovery | J16: Open | K16: accounting.fiscal_year_start_month
A17: CO-16 | B17: Calendar | C17: Time zone and date format | D17: Master > System Settings | E17: Asia/Manila; DD/MM/YYYY | G17: System Administrator | H17: Configuration | J17: Open | K17: general.timezone, general.date_format
A18: CO-17 | B18: Calendar | C18: Go-live date and first open accounting period | D18: Accounts > Period End > Period Management | E18: None | G18: Sponsor | H18: Mobilisation | J18: Open | K18: Drives cutover and opening balance date
... A23: CO-22 | B23: Hosting | C23: Planned maintenance window | D23: Not a system setting | E23: Saturday 20:00 to Sunday 06:00 PHT | G23: IT head | H23: Discovery | J23: Open | K23: Production Support Approach and Standards

Sheet Users and Roles
A1: ID | B1: Topic | C1: Question or configuration item | D1: BrokerVerse screen | E1: OOTB default | F1: Client answer | G1: Owner (broker) | H1: Needed by | I1: Due date | J1: Status | K1: Notes and setting key
A2: US-01 | B2: Users | C2: List of named users: full name, user name, e-mail, branch, department, role | D2: Master > Generals > User Management > User | E2: Administrator BrokerVerse only | G2: System Administrator | H2: Mock load 1 | J2: Open | K2: Users_Provisioning_Template.xlsx; user list due two weeks before training
A3: US-02 | B3: Roles | C3: Map each job title to one of the seven delivered roles | D3: Master > Generals > User Management > Role | E3: System Administrator, Sales & Marketing, Processing Team, Operations, Claims, Accounting, Accounting Manager | G3: Sponsor | H3: Discovery | J3: Open | K3: One role per user is the norm
A4: US-03 | B4: Roles | C4: Changes to the permissions of a delivered role | D4: Master > Generals > User Management > Role Permissions | E4: Delivered grants | G4: Sponsor | H4: Discovery | J4: Open | K4: Review with the User Access Matrix
A5: US-04 | B5: Administrators | C5: Names of the System Administrator and a deputy | D5: Master > Generals > User Management > User | E5: None | G5: IT head | H5: Mobilisation | J5: Open | K5: At least two recommended
A6: US-05 | B6: Approvers | C6: Names of a second Accounting Manager and second checkers for each maker-checker flow | D6: Master > Generals > User Management > User | E6: None | G6: Accounting Manager | H6: Discovery | J6: Open | K6: Maker and checker must be different users
A7: US-06 | B7: Security | C7: Roles that must use two-step verification (authenticator app) | D7: Master > Configuration (Security & Access) | E7: None | G7: IT head | H7: Configuration | J7: Open | K7: security.require_2fa_roles; recommended system-admin, accounting, accounting-manager
A8: US-07 | B8: Security | C8: Password policy: length, character classes, history, maximum age | D8: Master > Configuration (Security & Access) | E8: 8 characters; upper, lower, digit, symbol; last 5 refused; 90 days | G8: IT head | H8: Configuration | J8: Open | K8: security.password_*
A9: US-08 | B9: Security | C9: Failed sign-ins before the account is locked | D9: Master > Configuration (Security & Access) | E9: 5 | G9: IT head | H9: Configuration | J9: Open | K9: limits.max_login_attempts
A10: US-09 | B10: Security | C10: Sign-in attempts per IP and user name | D10: Master > Configuration (Security & Access) | E10: 10 per 300 seconds | G10: IT head | H10: Configuration | J10: Open | K10: security.login_rate_limit
A11: US-10 | B11: Security | C11: Idle sign-out | D11: Master > Configuration (Security & Access) | E11: 30 minutes | G11: IT head | H11: Configuration | J11: Open | K11: limits.session_idle_minutes
A12: US-11 | B12: Security | C12: Days without sign-in before an account is deactivated | D12: Master > Configuration (Security & Access) | E12: 90 days | G12: IT head | H12: Configuration | J12: Open | K12: access.dormant_days
A13: US-12 | B13: Scope | C13: Roles that see only their own book (records and clients they own) | D13: Master > Configuration (Security & Access) | E13: None | G13: Sponsor | H13: Discovery | J13: Open | K13: security.scoped_roles
... A15: US-14 | B15: Access reviews | C15: Frequency and reviewer of access recertification | D15: Master > Generals > User Management > Access Reviews | E15: Not scheduled | G15: IT head | H15: Discovery | J15: Open | K15: Twice a year recommended
A16: US-15 | B16: Delegations | C16: Delegations of approval authority needed at go-live (leave, travel) | D16: Master > Generals > User Management > Delegations | E16: None | G16: Accounting Manager | H16: UAT | J16: Open
A17: US-16 | B17: Commission | C17: Roles that earn commission on the policies they produce | D17: Master > Configuration (Commission & Incentives) | E17: Sales & Marketing | G17: Sales head | H17: Discovery | J17: Open | K17: commission.eligible_roles
A18: US-17 | B18: Notifications | C18: Roles told when a client approves a quotation | D18: Master > Configuration (Sales, Quotations & Placement) | E18: Processing Team | G18: Sales head | H18: Discovery | J18: Open | K18: quotations.approval_notify_roles
A19: US-18 | B19: Notifications | C19: Roles that approve renewals | D19: Master > Configuration (Policies, Endorsements & Renewals) | E19: Processing Team | G19: Operations head | H19: Discovery | J19: Open | K19: renewals.approver_roles

Sheet Insurers
A1: ID | B1: Topic | C1: Question or configuration item | D1: BrokerVerse screen | E1: OOTB default | F1: Client answer | G1: Owner (broker) | H1: Needed by | I1: Due date | J1: Status | K1: Notes and setting key
A2: IN-01 | B2: Insurer master | C2: Insurers the broker places with: legal name, short name, code, TIN, address | D2: Master > Generals > Insurance Management > Insurance Company | E2: Six Philippine non-life insurers seeded (MAPFRE, Malayan, Pioneer, FPG, Standard, Mercantile) with example contact e-mails | G2: Processing Team lead | H2: Mock load 1 | J2: Open | K2: Insurance_Company_Upload_Template.xlsx; replace example e-mails
A3: IN-02 | B3: Insurer master | C3: Default commission rate per insurer | D3: Master > Generals > Insurance Management > Insurance Company | E3: 14% to 17.5% on the seeded insurers | G3: Accounting Manager | H3: Mock load 1 | J3: Open | K3: Rate matrix rows override it
A4: IN-03 | B4: Credit terms | C4: Premium payment warranty days per insurer | D4: Master > Generals > Insurance Management > Insurance Company | E4: Blank | G4: Accounting Manager | H4: Mock load 1 | J4: Open | K4: Field Premium Payment Warranty (days)
A5: IN-04 | B5: Credit terms | C5: Remittance terms: days after collection per insurer | D5: Master > Generals > Insurance Management > Insurance Company | E5: Blank; fallback 30 days | G5: Accounting Manager | H5: Mock load 1 | J5: Open | K5: Field Remittance Terms; remittance.default_due_days
A6: IN-05 | B6: Billing | C6: Default billing mode per insurer: broker billed or direct bill | D6: Master > Generals > Insurance Management > Insurance Company | E6: Broker billed | G6: Accounting Manager | H6: Discovery | J6: Open | K6: Field Default Billing Mode; direct_bill.default_billing_mode
A7: IN-06 | B7: Contacts | C7: Underwriting, claims and accounting contacts per insurer (for slips, loss advice, remittance statements, debit notes) | D7: Master > Generals > Insurance Management > Insurance Company | E7: Example addresses only | G7: Processing Team lead | H7: Configuration | J7: Open
A8: IN-07 | B8: Claims | C8: Default recipient of the preliminary loss advice | D8: Master > Configuration (Claims) | E8: claims@brokerverse.local (placeholder) | G8: Claims head | H8: Configuration | J8: Open | K8: claims.pla_default_recipient; replace before go-live
A9: IN-08 | B9: Statements | C9: Format of each insurer statement of account (columns, file type) and a sample file | D9: Master > Finance > Insurer Statement Formats | E9: None | G9: Accounting | H9: Configuration | J9: Open | K9: Used by Accounts > Insurer Reconciliation
A10: IN-09 | B10: Co-insurance | C10: Lines usually co-insured; lead insurer practice; who confirms shares | D10: Operations > Sales & Marketing > Placement Slips | E10: Shares must total 100%; rounding to the lead | G10: Processing Team lead | H10: Discovery | J10: Open
A11: IN-10 | B11: Placement | C11: Days an insurer offer stays valid | D11: Master > Configuration (Sales, Quotations & Placement) | E11: 30 days | G11: Processing Team lead | H11: Discovery | J11: Open | K11: placement.offer_validity_days
A12: IN-11 | B12: Signatories | C12: Authorised signatories printed on documents | D12: Master > Generals > Insurance Management > Signatories | E12: None in production | G12: Sponsor | H12: Configuration | J12: Open | K12: Signatories_Upload_Template.xlsx
A13: IN-12 | B13: Reinsurance | C13: Does the broker arrange reinsurance? Reinsurers and treaties | D13: Master > Finance > Reinsurance Treaty | E13: Minimum security rating A-; treaty approval required; retention target 65% | G13: Processing Team lead | H13: Discovery | J13: Open | K13: reinsurance.*; skip if not used
A14: IN-13 | B14: Direct bill | C14: EWT the insurer withholds on direct-bill commission | D14: Master > Finance > Taxation | E14: WC139 10% | G14: Accounting Manager | H14: Configuration | J14: Open | K14: direct_bill.insurer_ewt_code
A15: IN-14 | B15: Direct bill | C15: Commission debit note: title, remarks, due days, e-mail text | D15: Master > Configuration (Billing, Collections & Credit) | E15: Commission Debit Note; 30 days | G15: Accounting Manager | H15: Configuration | J15: Open | K15: direct_bill.debit_note_*
A16: IN-15 | B16: Reconciliation | C16: Tolerance for remittance reconciliation differences | D16: Master > Configuration (Remittance & Reconciliation) | E16: PHP 0.50 | G16: Accounting Manager | H16: Configuration | J16: Open | K16: remittance.reconciliation_tolerance

Sheet Products and LOB
A1: ID | B1: Topic | C1: Question or configuration item | D1: BrokerVerse screen | E1: OOTB default | F1: Client answer | G1: Owner (broker) | H1: Needed by | I1: Due date | J1: Status | K1: Notes and setting key
A2: PR-01 | B2: Lines | C2: Lines of business written; the three with the most premium | D2: Master > Generals > Insurance Management > Line of Business | E2: Philippine non-life lines delivered | G2: Sales head | H2: Discovery | J2: Open | K2: Number of lines drives the implementation fee
A3: PR-02 | B3: Products | C3: Products per line, mapped to the delivered products | D3: Master > Generals > Insurance Management > Product | E3: Motor, CTPL, Fire, Marine Cargo, PA, CGL, Group EB, Surety Bond; travel, householder, micro-insurance, group PA, CAR, EAR, machinery breakdown, marine hull, money and securities | G3: Processing Team lead | H3: Discovery | J3: Open | K3: Product_Upload_Template.xlsx for additions
A4: PR-03 | B4: Products | C4: Policy types per product | D4: Master > Generals > Insurance Management > Product | E4: For example Comprehensive, TPL, Own Damage / Theft; Residential, Commercial; Import, Domestic | G4: Processing Team lead | H4: Configuration | J4: Open | K4: Policy_Type_Upload_Template.xlsx
A5: PR-04 | B5: Products | C5: Package or non-package classification per product | D5: Master > Generals > Insurance Management > Product | E5: Set per delivered product | G5: Processing Team lead | H5: Discovery | J5: Open | K5: Drives the placement journey
A6: PR-05 | B6: Products | C6: Tax regime per product: VAT or premium tax | D6: Master > Generals > Insurance Management > Product | E6: As delivered per product | G6: Accounting Manager | H6: Discovery | J6: Open | K6: Confirm with each insurer
A7: PR-06 | B7: Covers | C7: Covers and limits offered; excess bodily injury and property damage limits on motor | D7: Master > Generals > Insurance Management > Cover | E7: BI and PD limits PHP 100,000.00 to 500,000.00 | G7: Processing Team lead | H7: Configuration | J7: Open | K7: quote.bodily_injury_limits, quote.property_damage_limits
A8: PR-07 | B8: Journey | C8: Placement journey per line: Request for Quotation, Quotation Slip, Placement Slip, Record Issued Policy | D8: Master > Configuration (Sales, Quotations & Placement) | E8: Motor: Quotation Slip required. Fire, IAR, Marine, Casualty, Engineering: Placement Slip required. Others optional | G8: Processing Team lead | H8: Discovery | J8: Open | K8: placement.journey
A9: PR-08 | B9: Motor | C9: Confirm the motor tariff, CTPL 1-year and 3-year amounts per vehicle class | D9: Product Configurator > Product Templates (MOT-003-2025) | E9: 2025 tariff, confirmed 29 September 2026 | G9: Processing Team lead | H9: Configuration | J9: Open | K9: motor.pricing_template_code
A10: PR-09 | B10: Motor | C10: Auto Passenger PA rates and limits | D10: Product Configurator > Product Templates | E10: Per seat from the motor template | G10: Processing Team lead | H10: Configuration | J10: Open
A11: PR-10 | B11: Motor | C11: Vehicle makes, models and variants to add | D11: Master > Generals > Insurance Management > Vehicle | E11: Toyota, Mitsubishi, Honda, Ford, Nissan, Hyundai, Suzuki, Isuzu with models | G11: Processing Team lead | H11: Mock load 1 | J11: Open | K11: Vehicle_* templates
A12: PR-11 | B12: KYC | C12: Identifiers required before issue, per line | D12: Master > Configuration (Policies, Endorsements & Renewals) | E12: Motor: ID type, number, image, chassis, motor and plate number | G12: Compliance officer | H12: Discovery | J12: Open | K12: policy.kyc_required_fields
A13: PR-12 | B13: KYC | C13: Accepted government ID documents | D13: Master > Configuration (Policies, Endorsements & Renewals) | E13: PhilSys ID, UMID, Passport, Driver's License, PRC ID, SSS ID, GSIS and others | G13: Compliance officer | H13: Discovery | J13: Open | K13: policy.kyc_id_types
A14: PR-13 | B14: Quick Quote | C14: Package bundles and insurer rate tables for Quick Quote and Compare Insurers | D14: Master > Finance > Package Bundles; Insurer Rate Tables | E14: Delivered bundles | G14: Sales head | H14: Configuration | J14: Open | K14: packages.*
A15: PR-14 | B15: Rules | C15: Acceptance rules and product approval workflows | D15: Product Configurator > Acceptance Rules; Approval Workflows | E15: Delivered rules | G15: Processing Team lead | H15: Configuration | J15: Open
A16: PR-15 | B16: Documents | C16: Policy schedule, quotation and endorsement layouts; wording to print | D16: Product Configurator > Document Manager | E16: Delivered layouts | G16: Processing Team lead | H16: Configuration | J16: Open | K16: Layout changes outside OOTB are change requests
A17: PR-16 | B17: Quotation | C17: Quotation validity; maker-checker on quotations; approval link validity | D17: Master > Configuration (Sales, Quotations & Placement) | E17: 30 days; on; 168 hours | G17: Sales head | H17: Discovery | J17: Open | K17: limits.quote_validity_days, workflow.quote_maker_checker, quotations.approval_link_ttl_hours
A18: PR-17 | B18: Policy | C18: Default policy term | D18: Master > Configuration (Policies, Endorsements & Renewals) | E18: 12 months | G18: Processing Team lead | H18: Discovery | J18: Open | K18: policies.default_term_months
A19: PR-18 | B19: Renewals | C19: Renewal timetable: pipeline, notices, grace, reinstatement | D19: Master > Configuration (Policies, Endorsements & Renewals) | E19: Pipeline 90 days; notices 60, 30, 15 days; grace 30 days; reinstatement 90 days | G19: Operations head | H19: Discovery | J19: Open | K19: renewals.pipeline_days, limits.renewal_notice_days, renewals.grace_period_days, renewals.reinstatement_days
A20: PR-19 | B20: Renewals | C20: Renewal pricing: claims loading, loyalty discount, maker-checker | D20: Master > Configuration (Policies, Endorsements & Renewals) | E20: Loading 10% (cap 30%); loyalty 2% (cap 10%); maker-checker on | G20: Operations head | H20: Discovery | J20: Open | K20: renewals.claims_loading_*, renewals.loyalty_discount_*
A21: PR-20 | B21: Claims | C21: Claims controls: refuse claims on unpaid premium, check loss date, settlement maker-checker, SLA days, ageing | D21: Master > Configuration (Claims) | E21: On; on; on; 20 days; 7, 15, 30 days | G21: Claims head | H21: Discovery | J21: Open | K21: claims.block_unpaid_premium, claims.sla_days, claims.aging_thresholds
A22: PR-21 | B22: Packages | C22: Pro-rata pricing of section endorsements on package policies | D22: Master > Configuration (Sales, Quotations & Placement) | E22: On | G22: Processing Team lead | H22: Discovery | J22: Open | K22: packages.endorsement_prorata
A23: PR-22 | B23: Prospects | C23: Age limits for a prospect or client date of birth | D23: Master > Configuration (Sales, Quotations & Placement) | E23: 18 to 100 years | G23: Sales head | H23: Configuration | J23: Open | K23: leads.min_age_years, leads.max_age_years

Sheet Commission Rates
A1: ID | B1: Topic | C1: Question or configuration item | D1: BrokerVerse screen | E1: OOTB default | F1: Client answer | G1: Owner (broker) | H1: Needed by | I1: Due date | J1: Status | K1: Notes and setting key
A2: CM-01 | B2: Insurer commission | C2: Commission rate by insurer, product or line, new or renewal, with effective dates | D2: Master > Finance > Commission Rate Matrix | E2: Fallback 15% | G2: Accounting Manager | H2: Configuration | J2: Open | K2: commission.default_rate; no upload template, entered on screen
A3: CM-02 | B3: Referrers | C3: Referrers and sub-agents: name, payee type, TIN, bank account | D3: Commission > Agents/Referrer Accounts | E3: None in production | G3: Accounting | H3: Mock load 1 | J3: Open | K3: A referrer needs a bank account before payout (commission.require_bank_account)
A4: CM-03 | B4: Sharing | C4: Sub-agent (comsub) share by level | D4: Master > Configuration (Commission & Incentives) | E4: Level 1 8%; level 2 5% | G4: Sales head | H4: Discovery | J4: Open | K4: commission.comsub_rate_by_level
A5: CM-04 | B5: Withholding | C5: Withholding tax code per payee type | D5: Master > Configuration (Commission & Incentives) | E5: Agent WI515 5%; Sub-agent WI515 5%; External WC515 10% | G5: Accounting Manager | H5: Discovery | J5: Open | K5: commission.wht_code_by_type; confirm with the tax adviser
A6: CM-05 | B6: Payout rule | C6: Commission payable only when the premium is fully paid | D6: Master > Configuration (Commission & Incentives) | E6: On; eligible automatically on full payment | G6: Accounting Manager | H6: Discovery | J6: Open | K6: commission.require_full_payment, commission.auto_eligible_on_full_payment
A7: CM-06 | B7: Commission master | C7: Commission master records (codes) used by sales | D7: Master > Generals > Commission | E7: COM- series | G7: Sales head | H7: Configuration | J7: Open
A8: CM-07 | B8: VAT | C8: Is the broker VAT-registered; is commission quoted VAT-inclusive | D8: Master > Configuration (Billing, Collections & Credit) | E8: VAT-registered: yes; VAT-inclusive: no | G8: Accounting Manager | H8: Discovery | J8: Open | K8: direct_bill.broker_vat_registered, direct_bill.commission_vat_inclusive
A9: CM-08 | B9: Incentives | C9: Incentive programmes for sales staff: basis, period, targets, payout | D9: Master > Finance > Incentive Programs | E9: None in production | G9: Sales head | H9: Configuration | J9: Open | K9: Skip if not used
A10: CM-09 | B10: Open balances | C10: Commission due to referrers earned before go-live | D10: Accounts > Disbursement | E10: Part of the commission payable opening balance | G10: Accounting | H10: Mock load 1 | J10: Open | K10: Paid with payment vouchers

Sheet Chart of Accounts
A1: ID | B1: Topic | C1: Question or configuration item | D1: BrokerVerse screen | E1: OOTB default | F1: Client answer | G1: Owner (broker) | H1: Needed by | I1: Due date | J1: Status | K1: Notes and setting key
A2: GL-01 | B2: Chart | C2: Adopt the delivered Philippine broker chart of accounts, or map the broker's chart to it | D2: Master > Finance > Account Category; Main Account; Sub Account | E2: Delivered chart of about 110 accounts | G2: Accounting Manager | H2: Discovery | J2: Open | K2: Chart_of_Accounts_Upload_Template.xlsx
A3: GL-02 | B3: Chart | C3: Premium trust account and other bank GL accounts needed | D3: Master > Finance > Main Account; Sub Account | E3: Cash in Bank: Operating, E-wallet Clearing, Premium Trust, Payroll | G3: Accounting Manager | H3: Discovery | J3: Open
A4: GL-03 | B4: Account determination | C4: GL account for cash on hand | D4: Master > Finance > Account Determination | E4: 1101001 | G4: Accounting Manager | H4: Configuration | J4: Open | K4: accounting.account.*
A5: GL-04 | B5: Account determination | C5: GL account for cash in bank (default) | D5: Master > Finance > Account Determination | E5: 1102001 | G5: Accounting Manager | H5: Configuration | J5: Open | K5: accounting.account.*
A6: GL-05 | B6: Account determination | C6: GL account for petty cash fund | D6: Master > Finance > Account Determination | E6: 1103001 | G6: Accounting Manager | H6: Configuration | J6: Open | K6: accounting.account.*
A7: GL-06 | B7: Account determination | C7: GL account for premium receivable | D7: Master > Finance > Account Determination | E7: 1202001 | G7: Accounting Manager | H7: Configuration | J7: Open | K7: accounting.account.*
A8: GL-07 | B8: Account determination | C8: GL account for commission receivable | D8: Master > Finance > Account Determination | E8: 1203001 | G8: Accounting Manager | H8: Configuration | J8: Open | K8: accounting.account.*
A9: GL-08 | B9: Account determination | C9: GL account for agent receivable | D9: Master > Finance > Account Determination | E9: 1204001 | G9: Accounting Manager | H9: Configuration | J9: Open | K9: accounting.account.*
A10: GL-09 | B10: Account determination | C10: GL account for insurer refund receivable | D10: Master > Finance > Account Determination | E10: 1203002 | G10: Accounting Manager | H10: Configuration | J10: Open | K10: accounting.account.*
A11: GL-10 | B11: Account determination | C11: GL account for employee advances | D11: Master > Finance > Account Determination | E11: 1205001 | G11: Accounting Manager | H11: Configuration | J11: Open | K11: accounting.account.*
A12: GL-11 | B12: Account determination | C12: GL account for input vat | D12: Master > Finance > Account Determination | E12: 1301001 | G12: Accounting Manager | H12: Configuration | J12: Open | K12: accounting.account.*
A13: GL-12 | B13: Account determination | C13: GL account for creditable withholding tax | D13: Master > Finance > Account Determination | E13: 1302001 | G13: Accounting Manager | H13: Configuration | J13: Open | K13: accounting.account.*
A14: GL-13 | B14: Account determination | C14: GL account for output vat | D14: Master > Finance > Account Determination | E14: 2204003 | G14: Accounting Manager | H14: Configuration | J14: Open | K14: accounting.account.*
A15: GL-14 | B15: Account determination | C15: GL account for due to insurers | D15: Master > Finance > Account Determination | E15: 2201001 | G15: Accounting Manager | H15: Configuration | J15: Open | K15: accounting.account.*
... A28: GL-27 | B28: Write-off | C28: Write-off reasons, GL account and maximum amount | D28: Master > Finance > Account Determination | E28: Delivered reasons | G28: Accounting Manager | H28: Configuration | J28: Open | K28: Write_off_Reason_Upload_Template.xlsx
A29: GL-28 | B29: Close | C29: Month-end close checklist items | D29: Master > Finance > Close Checklist | E29: Delivered checklist incl. sub-ledger tie-out and bank reconciliation | G29: Accounting Manager | H29: Configuration | J29: Open
A30: GL-29 | B30: Close | C30: Recurring journals (rent, depreciation, accruals) | D30: Accounts > Period End > Recurring Journals | E30: None | G30: Accounting | H30: UAT | J30: Open
A31: GL-30 | B31: Opening balances | C31: Trial balance at the day before go-live and its date | D31: Accounts > Period End > Period Management (Import opening balances) | E31: None | G31: Accounting Manager | H31: Mock load 1 | J31: Open | K31: Opening_Balances_Upload_Template.xlsx
A32: GL-31 | B32: Currency | C32: Currencies used and source of exchange rates | D32: Master > Finance > Currency; Exchange Rate | E32: PHP base; USD, EUR, SGD, JPY | G32: Accounting Manager | H32: Configuration | J32: Open | K32: Exchange_Rate_Upload_Template.xlsx
A33: GL-32 | B33: Receivables | C33: Ageing buckets; receivable due days | D33: Master > Configuration (Billing, Collections & Credit) | E33: 30, 60, 90, 120 days; due in 30 days | G33: Accounting Manager | H33: Discovery | J33: Open | K33: limits.receivable_ageing_buckets, receivables.due_days
A34: GL-33 | B34: Collections | C34: Credit days, overdue levels, reminder timing | D34: Master > Configuration (Billing, Collections & Credit) | E34: 30 days; 30 and 60 days; 7 days before, every 7 days | G34: Accounting Manager | H34: Discovery | J34: Open | K34: collections.*
A35: GL-34 | B35: Petty cash | C35: Petty cash funds: custodian, amount, replenishment limit | D35: Master > Finance > Petty Cash | E35: None | G35: Accounting Manager | H35: Configuration | J35: Open | K35: PCF- codes
A36: GL-35 | B36: External ledger | C36: Will a corporate ledger be kept in another package? Export needs | D36: Reports > Financial Reports > Trial Balance; Journal | E36: Ledger kept in BrokerVerse | G36: Accounting Manager | H36: Discovery | J36: Open | K36: Excel or CSV export; a direct interface is a change request

Sheet Banks and Gateways
A1: ID | B1: Topic | C1: Question or configuration item | D1: BrokerVerse screen | E1: OOTB default | F1: Client answer | G1: Owner (broker) | H1: Needed by | I1: Due date | J1: Status | K1: Notes and setting key
A2: BK-01 | B2: Bank accounts | C2: Broker's bank accounts: bank, branch, account number, purpose (operating, premium trust, payroll), GL cash account | D2: Master > Finance > Bank | E2: Banks seeded: BDO, BPI, Metrobank, Land Bank, Security Bank, China Bank; no accounts | G2: Accounting Manager | H2: Mock load 1 | J2: Open | K2: Bank_Account_Upload_Template.xlsx
A3: BK-02 | B3: Statements | C3: Statement export format per account and one sample statement | D3: Master > Finance > Bank Statement Formats | E3: BDO-SAMPLE, BPI-SAMPLE, MBT-SAMPLE, GENERIC | G3: Accounting | H3: Configuration | J3: Open
A4: BK-03 | B4: Statements | C4: Reconcile-from date per account | D4: Master > Finance > Bank | E4: Go-live date | G4: Accounting Manager | H4: Mock load 1 | J4: Open | K4: Older items stay on the old reconciliation
A5: BK-04 | B5: Statements | C5: Bank transaction types: charges, interest, final tax, others | D5: Master > Finance > Bank Transaction Types | E5: Delivered types | G5: Accounting | H5: Configuration | J5: Open
A6: BK-05 | B6: Payments in | C6: How clients may pay | D6: Master > Configuration (Billing, Collections & Credit) | E6: Bank transfer, cheque, online, cash | G6: Accounting Manager | H6: Discovery | J6: Open | K6: policy.payment_capture_modes
A7: BK-06 | B7: Payments in | C7: Default payment mode on receipts; on disbursements | D7: Master > Configuration (Billing, Collections & Credit) | E7: Bank transfer; cheque | G7: Accounting | H7: Configuration | J7: Open | K7: receipts.default_payment_mode, disbursements.default_payment_mode
A8: BK-07 | B8: Gateway | C8: Online payment gateway to use: PayMongo, Dragonpay or none; merchant account owner | D8: Master > Finance > Payment Gateways | E8: PayMongo and Dragonpay off (sandbox mode); Sandbox gateway on (switch off in production) | G8: Accounting Manager | H8: Discovery | J8: Open | K8: Keys only in the secret store: PAYMONGO_*, DRAGONPAY_*
A9: BK-08 | B9: Gateway | C9: Methods offered and fee handling (absorbed or charged) | D9: Master > Finance > Payment Gateways | E9: Absorb; PayMongo 2.5%; Dragonpay PHP 20.00 | G9: Accounting Manager | H9: Configuration | J9: Open | K9: Confirm with the merchant agreement
A10: BK-09 | B10: Gateway | C10: Payment link validity; automatic official receipt on confirmed payment | D10: Master > Configuration (Billing, Collections & Credit) | E10: 72 hours; on | G10: Accounting Manager | H10: Configuration | J10: Open | K10: payments.link_validity_hours, payments.auto_receipt
A11: BK-10 | B11: Payments out | C11: Transfer methods to insurers (InstaPay, PESONet, RTGS, cheque) and who executes them in the bank portal | D11: Accounts > Remittance > Electronic Transfer | E11: Recorded and approved in BrokerVerse; executed in the bank portal | G11: Accounting Manager | H11: Discovery | J11: Open | K11: Bank payment files are a change request
A12: BK-11 | B12: Payments out | C12: Cheque series in use per account | D12: Accounts > Disbursement | E12: None | G12: Accounting | H12: Mock load 1 | J12: Open
A13: BK-12 | B13: Remittance | C13: Bank account used for remittance reconciliation | D13: Master > Configuration (Remittance & Reconciliation) | E13: Blank | G13: Accounting | H13: Configuration | J13: Open | K13: remittance.reconciliation_bank_account

Sheet Numbering Series
A1: ID | B1: Topic | C1: Question or configuration item | D1: BrokerVerse screen | E1: OOTB default | F1: Client answer | G1: Owner (broker) | H1: Needed by | I1: Due date | J1: Status | K1: Notes and setting key
A2: NU-01 | B2: Rules | C2: Continue the old system's numbers at go-live? Next number per series | D2: Master > Document Numbering | E2: Counters start at 1; can be set to continue | G2: Accounting Manager | H2: Configuration | J2: Open | K2: Counters only move forward
A3: NU-02 | B3: Series | C3: Lead: prefix, pattern and reset rule | D3: Master > Document Numbering | E3: LD, {PREFIX}-{YYYY}-{SEQ}, width 5, yearly reset | G3: System Administrator | H3: Configuration | J3: Open | K3: Series code lead
A4: NU-03 | B4: Series | C4: Quotation: prefix, pattern and reset rule | D4: Master > Document Numbering | E4: QT, {PREFIX}-{YYYY}-{SEQ}, width 5, yearly reset | G4: System Administrator | H4: Configuration | J4: Open | K4: Series code quote
A5: NU-04 | B5: Series | C5: Client Code: prefix, pattern and reset rule | D5: Master > Document Numbering | E5: CL, {PREFIX}-{YYYY}-{SEQ}, width 5, yearly reset | G5: System Administrator | H5: Configuration | J5: Open | K5: Series code client
A6: NU-05 | B6: Series | C6: Policy (when the insurer number is not given): prefix, pattern and reset rule | D6: Master > Document Numbering | E6: POL, {PREFIX}-{YYYY}-{SEQ}, width 5, yearly reset | G6: System Administrator | H6: Configuration | J6: Open | K6: Series code policy
A7: NU-06 | B7: Series | C7: Endorsement: prefix, pattern and reset rule | D7: Master > Document Numbering | E7: END, {PREFIX}-{YYYY}-{SEQ}, width 5, yearly reset | G7: System Administrator | H7: Configuration | J7: Open | K7: Series code endorsement
A8: NU-07 | B8: Series | C8: Renewal: prefix, pattern and reset rule | D8: Master > Document Numbering | E8: RN, {PREFIX}-{YYYY}-{SEQ}, width 5, yearly reset | G8: System Administrator | H8: Configuration | J8: Open | K8: Series code renewal
A9: NU-08 | B9: Series | C9: Renewal Quotation: prefix, pattern and reset rule | D9: Master > Document Numbering | E9: RQ, {PREFIX}-{YYYY}-{SEQ}, width 5, yearly reset | G9: System Administrator | H9: Configuration | J9: Open | K9: Series code renewal_quote
A10: NU-09 | B10: Series | C10: Renewal Batch: prefix, pattern and reset rule | D10: Master > Document Numbering | E10: RB, {PREFIX}-{YYYY}-{SEQ}, width 5, yearly reset | G10: System Administrator | H10: Configuration | J10: Open | K10: Series code renewal_batch
A11: NU-10 | B11: Series | C11: Win-back Campaign: prefix, pattern and reset rule | D11: Master > Document Numbering | E11: WB, {PREFIX}-{YYYY}-{SEQ}, width 5, yearly reset | G11: System Administrator | H11: Configuration | J11: Open | K11: Series code campaign
A12: NU-11 | B12: Series | C12: Claim: prefix, pattern and reset rule | D12: Master > Document Numbering | E12: CLM, {PREFIX}-{YYYY}-{SEQ}, width 5, yearly reset | G12: System Administrator | H12: Configuration | J12: Open | K12: Series code claim
A13: NU-12 | B13: Series | C13: Broker Slip: prefix, pattern and reset rule | D13: Master > Document Numbering | E13: BS, {PREFIX}-{YYYY}-{SEQ}, width 5, yearly reset | G13: System Administrator | H13: Configuration | J13: Open | K13: Series code broker_slip
... A63: NU-62 | B63: Master codes | C63: Petty Cash Code: prefix and pattern | D63: Master > Document Numbering | E63: PCF, {PREFIX}-{SEQ}, width 3, never reset | G63: System Administrator | H63: Configuration | J63: Open | K63: Series code petty_cash_fund

Sheet Approvals and Limits
A1: ID | B1: Topic | C1: Question or configuration item | D1: BrokerVerse screen | E1: OOTB default | F1: Client answer | G1: Owner (broker) | H1: Needed by | I1: Due date | J1: Status | K1: Notes and setting key
A2: AP-01 | B2: Authority matrix | C2: Approval limit: Quotation discount (percent), per role or named user | D2: Master > Generals > User Management > Authority Matrix | E2: Sales 10; Operations 10; Processing 15; Accounting Manager 25 | G2: Sponsor | H2: Configuration | J2: Open | K2: Transaction type quotation_discount; replace with the board-approved signing authority
A3: AP-02 | B3: Authority matrix | C3: Approval limit: Policy issue (sum insured, PHP), per role or named user | D3: Master > Generals > User Management > Authority Matrix | E3: Sales 1,000,000.00; Operations 1,000,000.00; Processing 5,000,000.00; Accounting Manager no limit | G3: Sponsor | H3: Configuration | J3: Open | K3: Transaction type policy_issue; replace with the board-approved signing authority
A4: AP-03 | B4: Authority matrix | C4: Approval limit: Return premium (PHP), per role or named user | D4: Master > Generals > User Management > Authority Matrix | E4: Operations 100,000.00; Processing 250,000.00; Accounting 250,000.00; Accounting Manager no limit | G4: Sponsor | H4: Configuration | J4: Open | K4: Transaction type return_premium; replace with the board-approved signing authority
A5: AP-04 | B5: Authority matrix | C5: Approval limit: Claim settlement (PHP), per role or named user | D5: Master > Generals > User Management > Authority Matrix | E5: Claims 1,000,000.00; Accounting Manager no limit | G5: Sponsor | H5: Configuration | J5: Open | K5: Transaction type claim_settlement; replace with the board-approved signing authority
A6: AP-05 | B6: Authority matrix | C6: Approval limit: Payment voucher (PHP), per role or named user | D6: Master > Generals > User Management > Authority Matrix | E6: Accounting 2,000,000.00; Accounting Manager no limit | G6: Sponsor | H6: Configuration | J6: Open | K6: Transaction type payment_voucher; replace with the board-approved signing authority
A7: AP-06 | B7: Authority matrix | C7: Approval limit: Journal voucher (PHP), per role or named user | D7: Master > Generals > User Management > Authority Matrix | E7: Accounting 1,000,000.00; Accounting Manager no limit | G7: Sponsor | H7: Configuration | J7: Open | K7: Transaction type journal_voucher; replace with the board-approved signing authority
A8: AP-07 | B8: Authority matrix | C8: Approval limit: Write-off (PHP), per role or named user | D8: Master > Generals > User Management > Authority Matrix | E8: Accounting 1,000.00; Accounting Manager 50,000.00 | G8: Sponsor | H8: Configuration | J8: Open | K8: Transaction type write_off; replace with the board-approved signing authority
A9: AP-08 | B9: Authority matrix | C9: Approval limit: Commission payout (PHP), per role or named user | D9: Master > Generals > User Management > Authority Matrix | E9: Accounting 500,000.00; Accounting Manager no limit | G9: Sponsor | H9: Configuration | J9: Open | K9: Transaction type commission_payout; replace with the board-approved signing authority
A10: AP-09 | B10: Authority matrix | C10: Approval limit: Petty cash (PHP), per role or named user | D10: Master > Generals > User Management > Authority Matrix | E10: Accounting 10,000.00; Accounting Manager 50,000.00 | G10: Sponsor | H10: Configuration | J10: Open | K10: Transaction type petty_cash; replace with the board-approved signing authority
A11: AP-10 | B11: Authority matrix | C11: Approval limit: Remittance (PHP), per role or named user | D11: Master > Generals > User Management > Authority Matrix | E11: Accounting 1,000,000.00; Accounting Manager no limit | G11: Sponsor | H11: Configuration | J11: Open | K11: Transaction type remittance; replace with the board-approved signing authority
A12: AP-11 | B12: Authority matrix | C12: Approval limit: Remittance settlement (PHP), per role or named user | D12: Master > Generals > User Management > Authority Matrix | E12: Accounting 1,000,000.00; Accounting Manager no limit | G12: Sponsor | H12: Configuration | J12: Open | K12: Transaction type remittance_settlement; replace with the board-approved signing authority
A13: AP-12 | B13: Authority matrix | C13: Who approves a new or changed limit (second administrator) | D13: Master > Generals > User Management > Authority Matrix | E13: Another administrator must approve | G13: Sponsor | H13: Configuration | J13: Open
A14: AP-13 | B14: Maker-checker | C14: Quotation approval before sending to the client | D14: Master > Configuration (Sales, Quotations & Placement) | E14: On | G14: Sales head | H14: Discovery | J14: Open | K14: workflow.quote_maker_checker
A15: AP-14 | B15: Maker-checker | C15: Renewal approval | D15: Master > Configuration (Policies, Endorsements & Renewals) | E15: On | G15: Operations head | H15: Discovery | J15: Open | K15: renewals.maker_checker
A16: AP-15 | B16: Maker-checker | C16: Claim settlement approval; settle automatically on approval | D16: Master > Configuration (Claims) | E16: On; on | G16: Claims head | H16: Discovery | J16: Open | K16: claims.settlement_maker_checker, claims.auto_settle_on_approval
A17: AP-16 | B17: Maker-checker | C17: Finance documents (payment vouchers, cheques, payouts, remittances, debit notes, petty cash) | D17: Master > Configuration (Accounting & Tax) | E17: On | G17: Accounting Manager | H17: Discovery | J17: Open | K17: finance.maker_checker_enabled
A18: AP-17 | B18: Maker-checker | C18: Journal voucher approval | D18: Master > Configuration (Accounting & Tax) | E18: On | G18: Accounting Manager | H18: Discovery | J18: Open | K18: journal.require_approval
A19: AP-18 | B19: Maker-checker | C19: Period close approval | D19: Master > Configuration (Accounting & Tax) | E19: On | G19: Accounting Manager | H19: Discovery | J19: Open | K19: accounting.period_close_requires_approval
A20: AP-19 | B20: Maker-checker | C20: Reinsurance treaty approval | D20: Master > Configuration (Remittance & Reconciliation) | E20: On | G20: Processing Team lead | H20: Discovery | J20: Open | K20: reinsurance.treaty_requires_approval
A21: AP-20 | B21: Maker-checker | C21: Posting rule and account determination changes | D21: Master > Finance > Configuration Approvals | E21: Second approver required | G21: Accounting Manager | H21: Discovery | J21: Open
A22: AP-21 | B22: Remittance | C22: Remittance approval levels by amount | D22: Accounts > Remittance > Approval Workflow | E22: Delivered levels | G22: Accounting Manager | H22: Discovery | J22: Open | K22: Confirm levels at the workshop
A23: AP-22 | B23: Credit control | C23: Client credit limits; instalment plan rules | D23: Accounts > Credit Control > Client Credit Limits; Instalment Plans | E23: None | G23: Accounting Manager | H23: Configuration | J23: Open
A24: AP-23 | B24: Notifications | C24: Approval request notifications to approvers and decision notices to makers | D24: Master > Configuration (Notifications & E-mail) | E24: On | G24: System Administrator | H24: Configuration | J24: Open | K24: notification.approval_requests

Sheet E-mail and Templates
A1: ID | B1: Topic | C1: Question or configuration item | D1: BrokerVerse screen | E1: OOTB default | F1: Client answer | G1: Owner (broker) | H1: Needed by | I1: Due date | J1: Status | K1: Notes and setting key
A2: EM-01 | B2: Sending | C2: Switch e-mail sending on (after the SMTP test) | D2: Master > Configuration (Notifications & E-mail) | E2: Off | G2: System Administrator | H2: UAT | J2: Open | K2: notification.email_enabled
A3: EM-02 | B3: Sending | C3: Sender name and address | D3: Master > Configuration (Notifications & E-mail) | E3: BrokerVerse <connect@iortatechnxt.com>: replace | G3: System Administrator | H3: Configuration | J3: Open | K3: notification.from_address
A4: EM-03 | B4: Sending | C4: Largest total attachment size per e-mail | D4: Master > Configuration (Notifications & E-mail) | E4: 10 MB | G4: System Administrator | H4: Configuration | J4: Open | K4: email.max_attachment_mb
A5: EM-04 | B5: Clients | C5: E-mail the official receipt PDF automatically when recorded; subject and text | D5: Master > Configuration (Billing, Collections & Credit) | E5: Off; delivered text | G5: Accounting Manager | H5: Configuration | J5: Open | K5: receipts.email_on_record, receipts.email_subject, receipts.email_template
A6: EM-05 | B6: Clients | C6: E-mail the premium invoice PDF automatically when issued; subject, text, payment instructions | D6: Master > Configuration (Billing, Collections & Credit) | E6: Off; delivered text | G6: Accounting Manager | H6: Configuration | J6: Open | K6: billing.email_on_issue, billing.email_*, billing.payment_instructions
A7: EM-06 | B7: Clients | C7: Premium payment reminder: subject and text | D7: Master > Configuration (Billing, Collections & Credit) | E7: Delivered text | G7: Accounting Manager | H7: Configuration | J7: Open | K7: collections.email_subject, collections.email_template
A8: EM-07 | B8: Clients | C8: Renewal notices: labels, subject and text; order enforced | D8: Master > Configuration (Policies, Endorsements & Renewals) | E8: First, Second, Final Notice; delivered text; order on | G8: Operations head | H8: Configuration | J8: Open | K8: renewals.notice_*
A9: EM-08 | B9: Clients | C9: Claim status updates and renewal reminders on or off | D9: Master > Configuration (Notifications & E-mail) | E9: On; on | G9: Operations head | H9: Configuration | J9: Open | K9: notification.claim_status, notification.renewal_reminder
A10: EM-09 | B10: Insurers | C10: Preliminary loss advice: subject and text | D10: Master > Configuration (Claims) | E10: Delivered text | G10: Claims head | H10: Configuration | J10: Open | K10: claims.pla_subject, claims.pla_template
A11: EM-10 | B11: Insurers | C11: Commission debit note e-mail | D11: Master > Configuration (Billing, Collections & Credit) | E11: Delivered text | G11: Accounting Manager | H11: Configuration | J11: Open | K11: direct_bill.email_subject, direct_bill.email_body
A12: EM-11 | B12: Insurers | C12: Remittance statement and agency bill e-mails | D12: Master > Configuration (Remittance & Reconciliation) | E12: Delivered text | G12: Accounting Manager | H12: Configuration | J12: Open | K12: remittance.statement_email_*, remittance.bill_email_*
A13: EM-12 | B13: Users | C13: Password reset e-mail | D13: Master > Configuration (Security & Access) | E13: Delivered text; code valid 15 minutes | G13: IT head | H13: Configuration | J13: Open | K13: security.reset_email_*, security.reset_code_minutes
... A19: EM-18 | B19: Privacy | C19: Privacy notice version recorded with consents | D19: Master > Configuration (Data Retention, Privacy & Uploads) | E19: 1.0 | G19: DPO | H19: Configuration | J19: Open | K19: privacy.notice_version

Sheet Taxes and LGU
A1: ID | B1: Topic | C1: Question or configuration item | D1: BrokerVerse screen | E1: OOTB default | F1: Client answer | G1: Owner (broker) | H1: Needed by | I1: Due date | J1: Status | K1: Notes and setting key
A2: TX-01 | B2: Premium taxes | C2: DST on premium: method (12.5% or PHP 0.50 per PHP 4.00 unit, fraction rounded up) as each insurer applies it | D2: Master > Finance > Premium Taxes & LGU Rates | E2: Per unit, PHP 0.50 per PHP 4.00 (12.5%) | G2: Accounting Manager | H2: Discovery | J2: Open | K2: Rule DST
A3: TX-02 | B3: Premium taxes | C3: VAT on premium for products under the VAT regime | D3: Master > Finance > Premium Taxes & LGU Rates | E3: 12% | G3: Accounting Manager | H3: Discovery | J3: Open | K3: Rule VAT
A4: TX-03 | B4: Premium taxes | C4: Premium tax for products under the premium tax regime | D4: Master > Finance > Premium Taxes & LGU Rates | E4: 2% | G4: Accounting Manager | H4: Discovery | J4: Open | K4: Rule PT
A5: TX-04 | B5: Premium taxes | C5: Fire service tax: lines to which it applies | D5: Master > Finance > Premium Taxes & LGU Rates | E5: 2% on fire lines (fire, IAR, householder) | G5: Accounting Manager | H5: Discovery | J5: Open | K5: Rule FST
A6: TX-05 | B6: LGU | C6: LGT rate per city or municipality where clients are located | D6: Master > Finance > Premium Taxes & LGU Rates | E6: 0.75% when the location has no rate | G6: Accounting Manager | H6: Configuration | J6: Open | K6: Rule LGT and LGU tax rates
A7: TX-06 | B7: Other charges | C7: Other charges on premium (for example notarial fee) | D7: Master > Finance > Premium Taxes & LGU Rates | E7: Notarial fee rule delivered switched off | G7: Accounting Manager | H7: Discovery | J7: Open | K7: Rule NOTARIAL
A8: TX-07 | B8: Tax codes | C8: Confirm output and input VAT codes | D8: Master > Finance > Taxation | E8: VAT12-OUT, VAT12-IN, VAT0, VATEX | G8: Accounting Manager | H8: Configuration | J8: Open | K8: Confirm with the tax adviser
A9: TX-08 | B9: Tax codes | C9: Confirm EWT codes and ATC used by the broker | D9: Master > Finance > Taxation | E9: WC139, WC140, WI139, WI140, WI515, WI516, WC515, WC158, WI158, WC160, WI160, WC100, WI100, WC120, WI010, WI011, WC010, WC011 | G9: Accounting Manager | H9: Configuration | J9: Open | K9: bir.atc_by_payee
A10: TX-09 | B10: Tax codes | C10: Final withholding on bank interest | D10: Master > Finance > Taxation | E10: FWT-INT 20% | G10: Accounting Manager | H10: Configuration | J10: Open
A11: TX-10 | B11: VAT status | C11: VAT-registered or non-VAT (percentage tax) | D11: Master > Configuration (Billing, Collections & Credit) | E11: VAT-registered | G11: Accounting Manager | H11: Discovery | J11: Open | K11: direct_bill.broker_vat_registered; no percentage tax working paper
A12: TX-11 | B12: BIR forms | C12: Registered name, address, TIN of the withholding agent for BIR forms | D12: Master > Generals > Organization > Company | E12: From the letterhead company | G12: Accounting Manager | H12: Configuration | J12: Open | K12: bir.* settings are a fallback only
A13: TX-12 | B13: BIR forms | C13: Which BrokerVerse documents serve as registered invoices and receipts under the EOPT Act | D13: Master > Document Numbering | E13: INV, OR, DN series available | G13: Accounting Manager | H13: Discovery | J13: Open | K13: Decision with the tax adviser; registration is the broker's
A14: TX-13 | B14: BIR forms | C14: Computerized accounting system registration status and plan | D14: Not a system setting | E14: Not applicable | G14: Accounting Manager | H14: Discovery | J14: Open | K14: Philippine Regulatory Compliance Matrix
