Workbook

Sheet Summary
A1: BrokerVerse OOTB: Test Execution Summary
A3: Product | B3: BrokerVerse OOTB (Philippine non-life insurance broking platform)
A4: Prepared by | B4: iorta TechNXT QA
A5: Execution dates | B5: 03 to 04 October 2026
A6: Environment | B6: Production build on a fresh PostgreSQL database with the UAT data set (business date 04 October 2026, months May to October 2026)
A7: Evidence | B7: Backend regression run of 03 October 2026 (634 tests); front-end unit tests (43); end-to-end UAT cycle (371 steps); screen check of every menu screen for the administrator and six role users
A8: Status values | B8: Pass: result observed as expected. Fail: result differs; defect raised. Blocked: cannot be executed in this environment. Not Run: not executed in this cycle.
A10: Module | B10: Total | C10: Pass | D10: Fail | E10: Blocked | F10: Not Run | G10: Pass %
A11: Sign-in and security | B11: =COUNTIF('Test Cases'!$B$2:$B$498,A11) | C11: =COUNTIFS('Test Cases'!$B$2:$B$498,$A11,'Test Cases'!$M$2:$M$498,"Pass") | D11: =COUNTIFS('Test Cases'!$B$2:$B$498,$A11,'Test Cases'!$M$2:$M$498,"Fail") | E11: =COUNTIFS('Test Cases'!$B$2:$B$498,$A11,'Test Cases'!$M$2:$M$498,"Blocked") | F11: =COUNTIFS('Test Cases'!$B$2:$B$498,$A11,'Test Cases'!$M$2:$M$498,"Not Run") | G11: =IF(B11=0,0,C11/B11)
A12: User and role administration | B12: =COUNTIF('Test Cases'!$B$2:$B$498,A12) | C12: =COUNTIFS('Test Cases'!$B$2:$B$498,$A12,'Test Cases'!$M$2:$M$498,"Pass") | D12: =COUNTIFS('Test Cases'!$B$2:$B$498,$A12,'Test Cases'!$M$2:$M$498,"Fail") | E12: =COUNTIFS('Test Cases'!$B$2:$B$498,$A12,'Test Cases'!$M$2:$M$498,"Blocked") | F12: =COUNTIFS('Test Cases'!$B$2:$B$498,$A12,'Test Cases'!$M$2:$M$498,"Not Run") | G12: =IF(B12=0,0,C12/B12)
A13: Masters | B13: =COUNTIF('Test Cases'!$B$2:$B$498,A13) | C13: =COUNTIFS('Test Cases'!$B$2:$B$498,$A13,'Test Cases'!$M$2:$M$498,"Pass") | D13: =COUNTIFS('Test Cases'!$B$2:$B$498,$A13,'Test Cases'!$M$2:$M$498,"Fail") | E13: =COUNTIFS('Test Cases'!$B$2:$B$498,$A13,'Test Cases'!$M$2:$M$498,"Blocked") | F13: =COUNTIFS('Test Cases'!$B$2:$B$498,$A13,'Test Cases'!$M$2:$M$498,"Not Run") | G13: =IF(B13=0,0,C13/B13)
A14: Configuration and numbering | B14: =COUNTIF('Test Cases'!$B$2:$B$498,A14) | C14: =COUNTIFS('Test Cases'!$B$2:$B$498,$A14,'Test Cases'!$M$2:$M$498,"Pass") | D14: =COUNTIFS('Test Cases'!$B$2:$B$498,$A14,'Test Cases'!$M$2:$M$498,"Fail") | E14: =COUNTIFS('Test Cases'!$B$2:$B$498,$A14,'Test Cases'!$M$2:$M$498,"Blocked") | F14: =COUNTIFS('Test Cases'!$B$2:$B$498,$A14,'Test Cases'!$M$2:$M$498,"Not Run") | G14: =IF(B14=0,0,C14/B14)
A15: Product configurator | B15: =COUNTIF('Test Cases'!$B$2:$B$498,A15) | C15: =COUNTIFS('Test Cases'!$B$2:$B$498,$A15,'Test Cases'!$M$2:$M$498,"Pass") | D15: =COUNTIFS('Test Cases'!$B$2:$B$498,$A15,'Test Cases'!$M$2:$M$498,"Fail") | E15: =COUNTIFS('Test Cases'!$B$2:$B$498,$A15,'Test Cases'!$M$2:$M$498,"Blocked") | F15: =COUNTIFS('Test Cases'!$B$2:$B$498,$A15,'Test Cases'!$M$2:$M$498,"Not Run") | G15: =IF(B15=0,0,C15/B15)
A16: Go-live data load | B16: =COUNTIF('Test Cases'!$B$2:$B$498,A16) | C16: =COUNTIFS('Test Cases'!$B$2:$B$498,$A16,'Test Cases'!$M$2:$M$498,"Pass") | D16: =COUNTIFS('Test Cases'!$B$2:$B$498,$A16,'Test Cases'!$M$2:$M$498,"Fail") | E16: =COUNTIFS('Test Cases'!$B$2:$B$498,$A16,'Test Cases'!$M$2:$M$498,"Blocked") | F16: =COUNTIFS('Test Cases'!$B$2:$B$498,$A16,'Test Cases'!$M$2:$M$498,"Not Run") | G16: =IF(B16=0,0,C16/B16)
A17: Prospects and clients | B17: =COUNTIF('Test Cases'!$B$2:$B$498,A17) | C17: =COUNTIFS('Test Cases'!$B$2:$B$498,$A17,'Test Cases'!$M$2:$M$498,"Pass") | D17: =COUNTIFS('Test Cases'!$B$2:$B$498,$A17,'Test Cases'!$M$2:$M$498,"Fail") | E17: =COUNTIFS('Test Cases'!$B$2:$B$498,$A17,'Test Cases'!$M$2:$M$498,"Blocked") | F17: =COUNTIFS('Test Cases'!$B$2:$B$498,$A17,'Test Cases'!$M$2:$M$498,"Not Run") | G17: =IF(B17=0,0,C17/B17)
A18: Quick quote and compare insurers | B18: =COUNTIF('Test Cases'!$B$2:$B$498,A18) | C18: =COUNTIFS('Test Cases'!$B$2:$B$498,$A18,'Test Cases'!$M$2:$M$498,"Pass") | D18: =COUNTIFS('Test Cases'!$B$2:$B$498,$A18,'Test Cases'!$M$2:$M$498,"Fail") | E18: =COUNTIFS('Test Cases'!$B$2:$B$498,$A18,'Test Cases'!$M$2:$M$498,"Blocked") | F18: =COUNTIFS('Test Cases'!$B$2:$B$498,$A18,'Test Cases'!$M$2:$M$498,"Not Run") | G18: =IF(B18=0,0,C18/B18)
A19: Quotations and customer response | B19: =COUNTIF('Test Cases'!$B$2:$B$498,A19) | C19: =COUNTIFS('Test Cases'!$B$2:$B$498,$A19,'Test Cases'!$M$2:$M$498,"Pass") | D19: =COUNTIFS('Test Cases'!$B$2:$B$498,$A19,'Test Cases'!$M$2:$M$498,"Fail") | E19: =COUNTIFS('Test Cases'!$B$2:$B$498,$A19,'Test Cases'!$M$2:$M$498,"Blocked") | F19: =COUNTIFS('Test Cases'!$B$2:$B$498,$A19,'Test Cases'!$M$2:$M$498,"Not Run") | G19: =IF(B19=0,0,C19/B19)
A20: Request for quotation and placement | B20: =COUNTIF('Test Cases'!$B$2:$B$498,A20) | C20: =COUNTIFS('Test Cases'!$B$2:$B$498,$A20,'Test Cases'!$M$2:$M$498,"Pass") | D20: =COUNTIFS('Test Cases'!$B$2:$B$498,$A20,'Test Cases'!$M$2:$M$498,"Fail") | E20: =COUNTIFS('Test Cases'!$B$2:$B$498,$A20,'Test Cases'!$M$2:$M$498,"Blocked") | F20: =COUNTIFS('Test Cases'!$B$2:$B$498,$A20,'Test Cases'!$M$2:$M$498,"Not Run") | G20: =IF(B20=0,0,C20/B20)
A21: Policy issuance | B21: =COUNTIF('Test Cases'!$B$2:$B$498,A21) | C21: =COUNTIFS('Test Cases'!$B$2:$B$498,$A21,'Test Cases'!$M$2:$M$498,"Pass") | D21: =COUNTIFS('Test Cases'!$B$2:$B$498,$A21,'Test Cases'!$M$2:$M$498,"Fail") | E21: =COUNTIFS('Test Cases'!$B$2:$B$498,$A21,'Test Cases'!$M$2:$M$498,"Blocked") | F21: =COUNTIFS('Test Cases'!$B$2:$B$498,$A21,'Test Cases'!$M$2:$M$498,"Not Run") | G21: =IF(B21=0,0,C21/B21)
A22: Endorsements and cancellations | B22: =COUNTIF('Test Cases'!$B$2:$B$498,A22) | C22: =COUNTIFS('Test Cases'!$B$2:$B$498,$A22,'Test Cases'!$M$2:$M$498,"Pass") | D22: =COUNTIFS('Test Cases'!$B$2:$B$498,$A22,'Test Cases'!$M$2:$M$498,"Fail") | E22: =COUNTIFS('Test Cases'!$B$2:$B$498,$A22,'Test Cases'!$M$2:$M$498,"Blocked") | F22: =COUNTIFS('Test Cases'!$B$2:$B$498,$A22,'Test Cases'!$M$2:$M$498,"Not Run") | G22: =IF(B22=0,0,C22/B22)
... A46: Role-based access | B46: =COUNTIF('Test Cases'!$B$2:$B$498,A46) | C46: =COUNTIFS('Test Cases'!$B$2:$B$498,$A46,'Test Cases'!$M$2:$M$498,"Pass") | D46: =COUNTIFS('Test Cases'!$B$2:$B$498,$A46,'Test Cases'!$M$2:$M$498,"Fail") | E46: =COUNTIFS('Test Cases'!$B$2:$B$498,$A46,'Test Cases'!$M$2:$M$498,"Blocked") | F46: =COUNTIFS('Test Cases'!$B$2:$B$498,$A46,'Test Cases'!$M$2:$M$498,"Not Run") | G46: =IF(B46=0,0,C46/B46)
A47: Total | B47: =SUM(B11:B46) | C47: =SUM(C11:C46) | D47: =SUM(D11:D46) | E47: =SUM(E11:E46) | F47: =SUM(F11:F46) | G47: =IF(B47=0,0,C47/B47)
A49: Test Type | B49: Total | C49: Pass | D49: Fail | E49: Blocked | F49: Not Run
A50: Functional | B50: =COUNTIF('Test Cases'!$F$2:$F$498,A50) | C50: =COUNTIFS('Test Cases'!$F$2:$F$498,$A50,'Test Cases'!$M$2:$M$498,"Pass") | D50: =COUNTIFS('Test Cases'!$F$2:$F$498,$A50,'Test Cases'!$M$2:$M$498,"Fail") | E50: =COUNTIFS('Test Cases'!$F$2:$F$498,$A50,'Test Cases'!$M$2:$M$498,"Blocked") | F50: =COUNTIFS('Test Cases'!$F$2:$F$498,$A50,'Test Cases'!$M$2:$M$498,"Not Run")
A51: Negative | B51: =COUNTIF('Test Cases'!$F$2:$F$498,A51) | C51: =COUNTIFS('Test Cases'!$F$2:$F$498,$A51,'Test Cases'!$M$2:$M$498,"Pass") | D51: =COUNTIFS('Test Cases'!$F$2:$F$498,$A51,'Test Cases'!$M$2:$M$498,"Fail") | E51: =COUNTIFS('Test Cases'!$F$2:$F$498,$A51,'Test Cases'!$M$2:$M$498,"Blocked") | F51: =COUNTIFS('Test Cases'!$F$2:$F$498,$A51,'Test Cases'!$M$2:$M$498,"Not Run")
A52: Validation | B52: =COUNTIF('Test Cases'!$F$2:$F$498,A52) | C52: =COUNTIFS('Test Cases'!$F$2:$F$498,$A52,'Test Cases'!$M$2:$M$498,"Pass") | D52: =COUNTIFS('Test Cases'!$F$2:$F$498,$A52,'Test Cases'!$M$2:$M$498,"Fail") | E52: =COUNTIFS('Test Cases'!$F$2:$F$498,$A52,'Test Cases'!$M$2:$M$498,"Blocked") | F52: =COUNTIFS('Test Cases'!$F$2:$F$498,$A52,'Test Cases'!$M$2:$M$498,"Not Run")
A53: Integration | B53: =COUNTIF('Test Cases'!$F$2:$F$498,A53) | C53: =COUNTIFS('Test Cases'!$F$2:$F$498,$A53,'Test Cases'!$M$2:$M$498,"Pass") | D53: =COUNTIFS('Test Cases'!$F$2:$F$498,$A53,'Test Cases'!$M$2:$M$498,"Fail") | E53: =COUNTIFS('Test Cases'!$F$2:$F$498,$A53,'Test Cases'!$M$2:$M$498,"Blocked") | F53: =COUNTIFS('Test Cases'!$F$2:$F$498,$A53,'Test Cases'!$M$2:$M$498,"Not Run")
A54: Role access | B54: =COUNTIF('Test Cases'!$F$2:$F$498,A54) | C54: =COUNTIFS('Test Cases'!$F$2:$F$498,$A54,'Test Cases'!$M$2:$M$498,"Pass") | D54: =COUNTIFS('Test Cases'!$F$2:$F$498,$A54,'Test Cases'!$M$2:$M$498,"Fail") | E54: =COUNTIFS('Test Cases'!$F$2:$F$498,$A54,'Test Cases'!$M$2:$M$498,"Blocked") | F54: =COUNTIFS('Test Cases'!$F$2:$F$498,$A54,'Test Cases'!$M$2:$M$498,"Not Run")
A55: Report | B55: =COUNTIF('Test Cases'!$F$2:$F$498,A55) | C55: =COUNTIFS('Test Cases'!$F$2:$F$498,$A55,'Test Cases'!$M$2:$M$498,"Pass") | D55: =COUNTIFS('Test Cases'!$F$2:$F$498,$A55,'Test Cases'!$M$2:$M$498,"Fail") | E55: =COUNTIFS('Test Cases'!$F$2:$F$498,$A55,'Test Cases'!$M$2:$M$498,"Blocked") | F55: =COUNTIFS('Test Cases'!$F$2:$F$498,$A55,'Test Cases'!$M$2:$M$498,"Not Run")
A56: Accounting | B56: =COUNTIF('Test Cases'!$F$2:$F$498,A56) | C56: =COUNTIFS('Test Cases'!$F$2:$F$498,$A56,'Test Cases'!$M$2:$M$498,"Pass") | D56: =COUNTIFS('Test Cases'!$F$2:$F$498,$A56,'Test Cases'!$M$2:$M$498,"Fail") | E56: =COUNTIFS('Test Cases'!$F$2:$F$498,$A56,'Test Cases'!$M$2:$M$498,"Blocked") | F56: =COUNTIFS('Test Cases'!$F$2:$F$498,$A56,'Test Cases'!$M$2:$M$498,"Not Run")
A58: Priority | B58: Total | C58: Pass | D58: Fail | E58: Blocked | F58: Not Run
A59: High | B59: =COUNTIF('Test Cases'!$G$2:$G$498,A59) | C59: =COUNTIFS('Test Cases'!$G$2:$G$498,$A59,'Test Cases'!$M$2:$M$498,"Pass") | D59: =COUNTIFS('Test Cases'!$G$2:$G$498,$A59,'Test Cases'!$M$2:$M$498,"Fail") | E59: =COUNTIFS('Test Cases'!$G$2:$G$498,$A59,'Test Cases'!$M$2:$M$498,"Blocked") | F59: =COUNTIFS('Test Cases'!$G$2:$G$498,$A59,'Test Cases'!$M$2:$M$498,"Not Run")
A60: Medium | B60: =COUNTIF('Test Cases'!$G$2:$G$498,A60) | C60: =COUNTIFS('Test Cases'!$G$2:$G$498,$A60,'Test Cases'!$M$2:$M$498,"Pass") | D60: =COUNTIFS('Test Cases'!$G$2:$G$498,$A60,'Test Cases'!$M$2:$M$498,"Fail") | E60: =COUNTIFS('Test Cases'!$G$2:$G$498,$A60,'Test Cases'!$M$2:$M$498,"Blocked") | F60: =COUNTIFS('Test Cases'!$G$2:$G$498,$A60,'Test Cases'!$M$2:$M$498,"Not Run")
A61: Low | B61: =COUNTIF('Test Cases'!$G$2:$G$498,A61) | C61: =COUNTIFS('Test Cases'!$G$2:$G$498,$A61,'Test Cases'!$M$2:$M$498,"Pass") | D61: =COUNTIFS('Test Cases'!$G$2:$G$498,$A61,'Test Cases'!$M$2:$M$498,"Fail") | E61: =COUNTIFS('Test Cases'!$G$2:$G$498,$A61,'Test Cases'!$M$2:$M$498,"Blocked") | F61: =COUNTIFS('Test Cases'!$G$2:$G$498,$A61,'Test Cases'!$M$2:$M$498,"Not Run")
A63: Defects and observations open | B63: =COUNTIF('Defects and Observations'!$E$2:$E$9,"Open")

Sheet Test Cases
A1: TC ID | B1: Module | C1: Sub-module / Screen | D1: Persona (role) | E1: Test Scenario | F1: Test Type | G1: Priority | H1: Pre-conditions | I1: Test Steps | J1: Test Data | K1: Expected Result | L1: Actual Result | M1: Status | N1: Defect ID | O1: Executed By | P1: Executed On | Q1: Remarks | R1: Evidence
A2: BV-SEC-001 | B2: Sign-in and security | C2: Login | D2: System Administrator (BrokerVerse) | E2: Sign in with a valid user ID and password | F2: Functional | G2: High | H2: Application open at the Login page. User BrokerVerse is active. | I2: 1. Open the BrokerVerse URL in Chrome. 2. Enter the User ID and Password. 3. Click Login. | J2: User ID: BrokerVerse; Password: administrator password from the environment sheet | K2: Login succeeds and the Executive Dashboard opens. The user name shows in the header. The menu shows every top-level menu. | L2: As expected. | M2: Pass | O2: iorta TechNXT QA | P2: 03 October 2026 | R2: backend/test/core.test.js :: rejects a wrong password and accepts the admin [passed] Screen check /executive/dashboard: opened clean
A3: BV-SEC-002 | B3: Sign-in and security | C3: Login | D3: Any signed-in user | E3: Wrong password is refused with a generic message | F3: Negative | G3: High | H3: User maria.rivera is active. | I3: 1. Open the Login page. 2. Enter User ID maria.rivera and a wrong password. 3. Click Login. | J3: User ID: maria.rivera; Password: Wrong#Pass1 | K3: Message "Invalid username or password" is shown. The user stays on the Login page. The attempt is recorded in Sign-in history as "Wrong password". | L3: As expected. | M3: Pass | O3: iorta TechNXT QA | P3: 03 October 2026 | R3: backend/test/core.test.js :: rejects a wrong password and accepts the admin [passed] backend/test/security.test.js :: exposes sign-in history to administrators and to the user [passed]
A4: BV-SEC-003 | B4: Sign-in and security | C4: Login | D4: Any signed-in user | E4: Unknown user ID gets the same message as a wrong password | F4: Negative | G4: Medium | H4: None. | I4: 1. Open the Login page. 2. Enter a user ID that does not exist and any password. 3. Click Login. | J4: User ID: juan.notauser; Password: Any#Pass123 | K4: Message "Invalid username or password" (same wording as a wrong password, so the screen does not reveal whether the user exists). Sign-in history records "Unknown user ID". | L4: As expected. | M4: Pass | O4: iorta TechNXT QA | P4: 03 October 2026 | R4: backend/test/security.test.js :: rate limits sign-in per username and per IP (429 + Retry-After) and logs every attempt [passed] backend/test/security.test.js :: exposes sign-in history to administrators and to the user [passed]
A5: BV-SEC-004 | B5: Sign-in and security | C5: Login | D5: Any signed-in user | E5: Login with blank User ID and Password | F5: Validation | G5: Medium | H5: Login page open. | I5: 1. Leave User ID and Password empty. 2. Click Login. | J5: User ID: (blank); Password: (blank) | K5: Field messages "User ID is required" and "Password is required" are shown under the fields. No request is sent. | M5: Not Run | O5: iorta TechNXT QA | Q5: Sign-in screen render covered by the front-end test; field messages to be checked by hand in the next cycle. | R5: brokerverse/src/App.test.js :: renders the sign-in screen when signed out [passed]
A6: BV-SEC-005 | B6: Sign-in and security | C6: Lockout | D6: System Administrator (BrokerVerse) | E6: Account locks after the configured number of failed sign-ins | F6: Negative | G6: High | H6: Test user ana.buenaventura active. Master > Configuration > limits.max_login_attempts = 5. | I6: 1. Sign in as ana.buenaventura with a wrong password 5 times. 2. Sign in a 6th time with the correct password. 3. Sign in as BrokerVerse and open Master > Generals > User Management > User. 4. Find ana.buenaventura and check the status. | J6: User ID: ana.buenaventura; wrong password: Wrong#Pass1 (x5) | K6: Attempts 1 to 5 show "Invalid username or password". The 6th attempt shows "Account locked. Contact the administrator". The User list shows the user as Locked. | L6: As expected. | M6: Pass | O6: iorta TechNXT QA | P6: 03 October 2026 | Q6: Lock threshold read from limits.max_login_attempts (seeded 5). | R6: backend/test/security.test.js :: rate limits sign-in per username and per IP (429 + Retry-After) and logs every attempt [passed] backend/test/hardening.test.js :: unlocks a locked account and records it [passed]
A7: BV-SEC-006 | B7: Sign-in and security | C7: Lockout | D7: System Administrator (BrokerVerse) | E7: Administrator unlocks a locked user | F7: Functional | G7: High | H7: User ana.buenaventura is Locked (previous case). | I7: 1. Open Master > Generals > User Management > User. 2. Open the Account actions of ana.buenaventura. 3. Click Unlock and confirm. 4. Sign in as ana.buenaventura with the correct password. | J7: User: ana.buenaventura | K7: Confirmation "Unlock the account of ana.buenaventura? Failed sign-in attempts are cleared." Message "ana.buenaventura can sign in again." The user signs in. The unlock is in the Audit Trail. | L7: As expected. | M7: Pass | O7: iorta TechNXT QA | P7: 03 October 2026 | R7: backend/test/hardening.test.js :: unlocks a locked account and records it [passed] Screen check /master/generals/usermanagement/user: opened clean
A8: BV-SEC-007 | B8: Sign-in and security | C8: Lockout | D8: Any signed-in user | E8: Too many sign-in attempts from one address are throttled | F8: Negative | G8: Medium | H8: security.login_rate_limit = {"max":10,"windowSeconds":300}. | I8: 1. Submit 11 sign-in attempts for the same user ID within 5 minutes. 2. Read the message on the 11th attempt. | J8: User ID: paolo.dizon; Password: Wrong#Pass1 | K8: The 11th attempt is refused with "Too many attempts" (HTTP 429 with Retry-After). Every attempt is in Sign-in history. | L8: As expected. | M8: Pass | O8: iorta TechNXT QA | P8: 03 October 2026 | R8: backend/test/security.test.js :: rate limits sign-in per username and per IP (429 + Retry-After) and logs every attempt [passed]
A9: BV-SEC-008 | B9: Sign-in and security | C9: Password policy | D9: Any signed-in user | E9: Change password: rules shown and enforced | F9: Validation | G9: High | H9: Signed in as maria.rivera. Policy: 8 characters, upper, lower, digit, symbol, not one of last 5. | I9: 1. Open the user menu and click Change password. 2. Enter the current password. 3. Enter new password "brokerverse" in both new password fields. 4. Click Save and read the rules list. 5. Enter "Brokerverse#2026" in both fields and save. | J9: Weak: brokerverse; Strong: Brokerverse#2026 | K9: With the weak value the rules for upper-case, digit and symbol show "(not met yet)" and "The new password does not meet all the rules below." With the strong value: "Password changed. Your other sessions have been signed out." | L9: As expected. | M9: Pass | O9: iorta TechNXT QA | P9: 03 October 2026 | R9: backend/test/security.test.js :: enforces length, character classes and history on change-password [passed]
A10: BV-SEC-009 | B10: Sign-in and security | C10: Password policy | D10: Any signed-in user | E10: New password cannot repeat one of the last 5 passwords | F10: Negative | G10: Medium | H10: User has changed the password at least twice. | I10: 1. Open Change password. 2. Enter the current password. 3. Enter a password used two changes ago as the new password. 4. Click Save. | J10: Previous password: Brokerverse#2025 | K10: Change refused. Rule "Not one of your last 5 passwords" shows "(not met yet)". | L10: As expected. | M10: Pass | O10: iorta TechNXT QA | P10: 03 October 2026 | R10: backend/test/security.test.js :: enforces length, character classes and history on change-password [passed]
A11: BV-SEC-010 | B11: Sign-in and security | C11: Password policy | D11: Any signed-in user | E11: New password must differ from the current one and both entries must match | F11: Validation | G11: Low | H11: Signed in. | I11: 1. Open Change password. 2. Enter the current password as the new password and save. 3. Enter two different values in New password and Confirm new password and save. | J11: New: same as current; Confirm: Brokerverse#2027 vs Brokerverse#2028 | K11: Messages "The new password must differ from the current one." and "The two new passwords do not match." | L11: As expected. | M11: Pass | O11: iorta TechNXT QA | P11: 03 October 2026 | R11: backend/test/security.test.js :: enforces length, character classes and history on change-password [passed]
A12: BV-SEC-011 | B12: Sign-in and security | C12: Password policy | D12: System Administrator (BrokerVerse) | E12: New user created without a password gets a temporary password that must be changed | F12: Functional | G12: High | H12: Signed in as BrokerVerse. | I12: 1. Open Master > Generals > User Management > User and click Add User. 2. Fill the user details, role Claims, leave Password empty ("Leave empty for a temporary password"). 3. Click Save and copy the temporary password. 4. Sign in as the new user with the temporary password. | J12: Username: joy.macaraeg; Role: claims; Branch: HO | K12: The Temporary password dialog shows the password once. At first sign-in the user sees "You must choose a new password before you continue." and cannot open any screen until the password is changed. | L12: As expected. | M12: Pass | O12: iorta TechNXT QA | P12: 04 October 2026 | R12: backend/test/hardening.test.js :: generates a policy-compliant temporary password for a user created without one; it must be changed [passed] backend/test/core.test.js :: admin creates a persona user who can then sign in with that role [passed] UAT cycle 03-04 October 2026, phase Set-up (46 passed, 0 failed)
A13: BV-SEC-012 | B13: Sign-in and security | C13: Password policy | D13: Any signed-in user | E13: Expired password forces a change at sign-in | F13: Functional | G13: Medium | H13: security.password_max_age_days = 90. Test user whose password is older than 90 days. | I13: 1. Sign in with the user whose password is older than 90 days. | J13: User with password_changed_at older than 90 days | K13: Screen shows "Your password has expired. Choose a new one to continue." The user reaches the dashboard only after a compliant change. | L13: As expected. | M13: Pass | O13: iorta TechNXT QA | P13: 03 October 2026 | R13: backend/test/security.test.js :: flags mustChangePassword when the password is older than security.password_max_age_days [passed]
A14: BV-SEC-013 | B14: Sign-in and security | C14: Password reset | D14: Any signed-in user | E14: Forgot password with a verification code | F14: Functional | G14: Medium | H14: E-mail sending switched on and SMTP configured. | I14: 1. On the Login page click Forgot password?. 2. Enter the user ID and click Send code. 3. Open the e-mail and enter the verification code with a new password. 4. Click Reset password and sign in. | J14: User ID: liza.quiambao | K14: "If the account exists, a verification code has been sent." The code works once within 15 minutes; after the reset: "Your password has been reset. Sign in with the new password." | L14: Code handling confirmed in the backend run; delivery to a mailbox not possible: SMTP not configured in the test environment. | M14: Blocked | O14: iorta TechNXT QA | P14: 03 October 2026 | Q14: Re-test once the SMTP server is set. | R14: backend/test/configuration.test.js :: password reset e-mail and code lifetime follow security.reset_* settings [passed] backend/test/hardening.test.js :: stores reset codes hashed, keeps only the latest valid, withdraws a code after too many wrong entries [passed]
A15: BV-SEC-014 | B15: Sign-in and security | C15: Password reset | D15: Any signed-in user | E15: Reset code withdrawn after too many wrong entries | F15: Negative | G15: Medium | H15: A reset code has been requested. | I15: 1. Request a reset code. 2. Enter a wrong code 5 times. 3. Enter the correct code. | J15: security.reset_code_max_attempts = 5 | K15: After 5 wrong entries the code no longer works; a new code must be requested. Only the latest code is valid. | L15: As expected. | M15: Pass | O15: iorta TechNXT QA | P15: 03 October 2026 | R15: backend/test/hardening.test.js :: stores reset codes hashed, keeps only the latest valid, withdraws a code after too many wrong entries [passed]
A16: BV-SEC-015 | B16: Sign-in and security | C16: 2FA | D16: Any signed-in user | E16: Turn on two-step verification and sign in with the code | F16: Functional | G16: High | H16: Signed in as liza.quiambao. Authenticator app on a phone. | I16: 1. Open the user menu > Two-factor authentication and click Turn on. 2. Type the Setup key in the authenticator app. 3. Enter the 6-digit code and click Verify. 4. Sign out and sign in again with user ID and password. 5. Enter the code from the app. | J16: User: liza.quiambao; Issuer shown in app: BrokerVerse | K16: "Two-step verification is on." At the next sign-in the Two-step verification screen asks for the code; the dashboard opens after a valid code. | L16: As expected. | M16: Pass | O16: iorta TechNXT QA | P16: 03 October 2026 | R16: backend/test/security.test.js :: enrols, then requires the code at sign-in; disables with a code [passed] backend/test/security.test.js :: implements RFC 6238 / RFC 4226 correctly [passed]
A17: BV-SEC-016 | B17: Sign-in and security | C17: 2FA | D17: Any signed-in user | E17: Wrong two-step code is refused and checks are rate limited | F17: Negative | G17: High | H17: User with two-step verification on. | I17: 1. Sign in with user ID and password. 2. Enter 000000 as the code. 3. Repeat wrong codes several times. | J17: Code: 000000 | K17: "The code is not valid. Try the current code." Repeated wrong codes are throttled. Sign-in history records "Wrong authentication code". | L17: As expected. | M17: Pass | O17: iorta TechNXT QA | P17: 03 October 2026 | R17: backend/test/hardening.test.js :: rate limits two-factor code checks of a signed-in user [passed] backend/test/security.test.js :: exposes sign-in history to administrators and to the user [passed]
A18: BV-SEC-017 | B18: Sign-in and security | C18: 2FA | D18: System Administrator (BrokerVerse) | E18: Role that requires two-step verification must enrol before any screen | F18: Functional | G18: High | H18: Master > Configuration > Security: security.require_2fa_roles = ["accounting-manager"]. | I18: 1. Save the setting. 2. Sign in as teresa.villaroman (no two-step yet). | J18: Setting: security.require_2fa_roles = ["accounting-manager"] | K18: Screen "Set up two-step verification" with "Your role requires two-step verification. Set it up to continue." No menu screen opens until enrolment is done. "Turn off" is not offered to this user. | L18: As expected. | M18: Pass | O18: iorta TechNXT QA | P18: 03 October 2026 | R18: backend/test/security.test.js :: forces enrolment for roles in security.require_2fa_roles; administrators can reset a user's second factor [passed]
A19: BV-SEC-018 | B19: Sign-in and security | C19: 2FA | D19: System Administrator (BrokerVerse) | E19: Administrator turns off a user's two-step verification | F19: Functional | G19: Medium | H19: User liza.quiambao lost the phone. | I19: 1. Open Master > Generals > User Management > User. 2. Open Account actions of liza.quiambao. 3. Click Turn off two-step verification and confirm. | J19: User: liza.quiambao | K19: Message "Two-step verification turned off for liza.quiambao." The user signs in with password only. Action is in the Audit Trail. | L19: As expected. | M19: Pass | O19: iorta TechNXT QA | P19: 03 October 2026 | R19: backend/test/security.test.js :: forces enrolment for roles in security.require_2fa_roles; administrators can reset a user's second factor [passed]
A20: BV-SEC-019 | B20: Sign-in and security | C20: 2FA | D20: System Administrator (beatriz.lacson) | E20: A non-administrator user desk cannot reset 2FA or lock a System Administrator | F20: Negative | G20: High | H20: beatriz.lacson holds a user desk grant but is checked against the built-in administrator. | I20: 1. Open the User list. 2. Try to turn off two-step verification of BrokerVerse. 3. Try to lock BrokerVerse. 4. Try to change own roles. | J20: Target: BrokerVerse | K20: Each action is refused with a clear message. Nobody changes their own roles or status. | L20: As expected. | M20: Pass | O20: iorta TechNXT QA | P20: 03 October 2026 | R20: backend/test/hardening.test.js :: a non-administrator user desk cannot reset, lock or turn off 2FA of a System Administrator, nor change their own access [passed]
A21: BV-SEC-020 | B21: Sign-in and security | C21: Session | D21: Any signed-in user | E21: Idle session signs out after the configured minutes | F21: Functional | G21: Medium | H21: limits.session_idle_minutes = 30. | I21: 1. Sign in as maria.rivera. 2. Leave the browser idle for 29 minutes. 3. Read the warning. 4. Leave it idle 1 more minute. | J21: Idle time: 30 minutes | K21: At 29 minutes the banner "You will be signed out in one minute because of inactivity..." shows. At 30 minutes the user is returned to the Login page. | M21: Not Run | O21: iorta TechNXT QA | Q21: Timed test not run in this cycle; access token lifetime (30 minutes) confirmed in the backend run. | R21: backend/test/hardening.test.js :: defaults: 30-minute access tokens; development keeps its fallbacks [passed]
A22: BV-SEC-021 | B22: Sign-in and security | C22: Session | D22: System Administrator (BrokerVerse) | E22: Deactivating a user or changing the role ends access at once | F22: Functional | G22: High | H22: paolo.dizon signed in on another browser. | I22: 1. As BrokerVerse open the User list and deactivate paolo.dizon. 2. In the other browser click any menu. | J22: User: paolo.dizon | K22: The next request of paolo.dizon is refused and the browser returns to the Login page with the session ended. | L22: As expected. | M22: Pass | O22: iorta TechNXT QA | P22: 03 October 2026 | R22: backend/test/hardening.test.js :: ends access at once on deactivation and on role change; refresh issues a token with the new roles [passed]
A23: BV-SEC-022 | B23: Sign-in and security | C23: Session | D23: System Administrator (BrokerVerse) | E23: End every session of a user | F23: Functional | G23: Medium | H23: User signed in on two browsers. | I23: 1. Open Master > Generals > User Management > User Access Matrix. 2. Select the user and end all sessions. | J23: User: jose.bernardo | K23: Both browsers are signed out at the next request. | L23: As expected. | M23: Pass | O23: iorta TechNXT QA | P23: 03 October 2026 | R23: backend/test/access-control.test.js :: ends every session of a user [passed] Screen check /master/generals/usermanagement/access-matrix: opened clean
A24: BV-SEC-023 | B24: Sign-in and security | C24: Session | D24: Any signed-in user | E24: Reuse of an old refresh token revokes the sign-in | F24: Negative | G24: High | H24: Valid session. | I24: 1. Capture the refresh token after one renewal. 2. Present the old (rotated) refresh token again. | J24: Old refresh token | K24: The request is refused and the whole sign-in is revoked; Sign-in history shows "Session ended (token reuse)". | L24: As expected. | M24: Pass | O24: iorta TechNXT QA | P24: 03 October 2026 | R24: backend/test/hardening.test.js :: detects reuse of a rotated refresh token and revokes the whole sign-in [passed]
A25: BV-SEC-024 | B25: Sign-in and security | C25: Sign-in history | D25: System Administrator (BrokerVerse) | E25: Sign-in history visible to the administrator and the user | F25: Functional | G25: Low | H25: Some failed and successful sign-ins exist. | I25: 1. Open the User list and click Sign-in history for maria.rivera. 2. Sign in as maria.rivera and open own Sign-in history. | J25: User: maria.rivera | K25: Columns Date and time, Result, Detail, Method, IP address, Browser / device. Failed attempts show the reason. | L25: As expected. | M25: Pass | O25: iorta TechNXT QA | P25: 03 October 2026 | R25: backend/test/security.test.js :: exposes sign-in history to administrators and to the user [passed]
A26: BV-SEC-025 | B26: Sign-in and security | C26: API security | D26: System Administrator (BrokerVerse) | E26: Every non-public endpoint refuses a call without a token | F26: Negative | G26: High | H26: API reachable. | I26: 1. Call each non-public API route without the Authorization header. 2. Compare the public route list with the intended list. | J26: All registered routes | K26: Every non-public route answers 401. Only the intended public routes (sign-in, health, version, public settings, customer approval link, gateway callbacks) answer without a token. | L26: As expected. | M26: Pass | O26: iorta TechNXT QA | P26: 03 October 2026 | R26: backend/test/hardening.test.js :: every non-public route answers 401 without a token [passed] backend/test/hardening.test.js :: declares only the intended public routes [passed]
A27: BV-SEC-026 | B27: Sign-in and security | C27: API security | D27: System Administrator (BrokerVerse) | E27: Tokens other than HS256 and default secrets are refused | F27: Negative | G27: High | H27: Production configuration. | I27: 1. Present a token signed with another algorithm. 2. Start the API in production mode with a default secret, CORS * or a localhost base URL. | J27: alg=none token; JWT_SECRET=default | K27: Token refused. The API does not start in production with default secrets, CORS * or a localhost base URL. | L27: As expected. | M27: Pass | O27: iorta TechNXT QA | P27: 03 October 2026 | R27: backend/test/hardening.test.js :: accepts only HS256 tokens [passed] backend/test/hardening.test.js :: refuses missing or default secrets, CORS * and a localhost base URL in production only [passed]
A28: BV-SEC-027 | B28: Sign-in and security | C28: API security | D28: System Administrator (BrokerVerse) | E28: Injection probes in search and file fields | F28: Negative | G28: High | H28: Signed in. | I28: 1. Search a list with ' OR 1=1 -- and <script>alert(1)</script>. 2. Upload an .html file renamed .pdf as a document. 3. Export a list containing a cell starting with =HYPERLINK(. | J28: Search: ' OR 1=1 --; File: test.html renamed test.pdf; Cell: =HYPERLINK("x") | K28: Search returns no extra rows and no error page. The upload is refused (type read from the file signature). Exported CSV cells starting with = + - @ are guarded. | L28: As expected. | M28: Pass | O28: iorta TechNXT QA | P28: 03 October 2026 | R28: backend/test/hardening.test.js :: detects file types from their signature, not from the name or the browser [passed] backend/test/hardening.test.js :: refuses HTML, scripts and unknown binaries; stores the detected type [passed] backend/test/configuration.test.js :: CSV cells written by any module are guarded against spreadsheet formulas [passed]
A29: BV-SEC-028 | B29: Sign-in and security | C29: API security | D29: System Administrator (BrokerVerse) | E29: Security headers and request id on every response | F29: Functional | G29: Medium | H29: API reachable. | I29: 1. Open browser developer tools > Network. 2. Load any screen and inspect a response header set. | J29: Any API call | K29: Responses carry the standard security headers (X-Content-Type-Options, X-Frame-Options, Strict-Transport-Security, Content-Security-Policy) and x-request-id. Errors show a generic message with the request id. | L29: As expected. | M29: Pass | O29: iorta TechNXT QA | P29: 03 October 2026 | R29: backend/test/security.test.js :: adds x-request-id to every response, echoes a caller id and returns it in error bodies [passed] backend/test/hardening.test.js :: answers 500 with a generic message and the request id; client errors keep their message [passed]
A30: BV-SEC-029 | B30: Sign-in and security | C30: API security | D30: System Administrator (BrokerVerse) | E30: Upload size limit and global rate limit | F30: Negative | G30: Medium | H30: UPLOAD_MAX_MB set. | I30: 1. Upload a file larger than UPLOAD_MAX_MB. 2. Send API calls above the per-user rate limit. | J30: File: 30 MB PDF | K30: Large file refused with 413. Calls above the limit answer 429. | L30: As expected. | M30: Pass | O30: iorta TechNXT QA | P30: 03 October 2026 | R30: backend/test/hardening.test.js :: refuses uploads above UPLOAD_MAX_MB with 413 [passed] backend/test/hardening.test.js :: applies a configurable global API rate limit per user [passed]
A31: BV-SEC-030 | B31: Sign-in and security | C31: API security | D31: System Administrator (BrokerVerse) | E31: Tokens and cookies never written to the server log | F31: Functional | G31: Medium | H31: Server log available. | I31: 1. Sign in and use several screens. 2. Open the server log and search for "Bearer" and the refresh token value. | J31: Server log of the test session | K31: No bearer token, cookie or signed link token appears in the log. | L31: As expected. | M31: Pass | O31: iorta TechNXT QA | P31: 03 October 2026 | R31: backend/test/hardening.test.js :: never writes bearer tokens, cookies or link tokens to the log [passed]
A32: BV-SEC-031 | B32: Sign-in and security | C32: Documents | D32: Any signed-in user | E32: Document links open only with a session or a signed, unexpired link | F32: Negative | G32: High | H32: A policy document is stored. | I32: 1. Copy the document link from a policy. 2. Open it in a private window after the signature expiry. 3. Open a non-PDF attachment. | J32: Policy schedule PDF; claim photo | K32: Expired or unsigned link is refused. Non-image, non-PDF files download as attachments. | L32: As expected. | M32: Pass | O32: iorta TechNXT QA | P32: 03 October 2026 | R32: backend/test/hardening.test.js :: serves objects only with a bearer header or a signed, unexpired link, with safe headers [passed] backend/test/hardening.test.js :: sends non-image, non-PDF files as attachments; legacy unsafe types as octet-stream [passed]
A33: BV-SEC-032 | B33: Sign-in and security | C33: Dependency audit | D33: System Administrator (BrokerVerse) | E33: Dependency audit of the release build | F33: Functional | G33: High | H33: Release build of backend and front end. | I33: 1. Run npm audit --omit=dev in backend/. 2. Run npm audit --omit=dev in brokerverse/. | J33: Release lock files of 03 October 2026 | K33: No known vulnerability in runtime dependencies. | L33: Backend: 0 vulnerabilities. Front end runtime: 2 moderate findings in react-router (open redirect advisory); the fix needs a major upgrade. | M33: Fail | N33: BV-DEF-001 | O33: iorta TechNXT QA | P33: 03 October 2026
A34: BV-SEC-033 | B34: Sign-in and security | C34: Data protection | D34: System Administrator (BrokerVerse) | E34: Personal data encrypted at application level | F34: Functional | G34: Medium | H34: Database access for the tester. | I34: 1. Create a client with TIN, mobile and ID number. 2. Query the clients table directly. 3. Query the users table for TOTP secrets. | J34: Client: Rowena Bautista; TIN 214-558-902-000 | K34: Sensitive personal fields are stored encrypted. | L34: Only two-step verification secrets are encrypted (DATA_ENCRYPTION_KEY). Client personal fields are stored in plain columns; protection relies on database and disk encryption. | M34: Fail | N34: BV-DEF-003 | O34: iorta TechNXT QA | P34: 03 October 2026 | R34: backend/test/hardening.test.js :: encrypts TOTP secrets with DATA_ENCRYPTION_KEY [passed]
A35: BV-SEC-034 | B35: Sign-in and security | C35: Data privacy | D35: Operations / Client Service (ana.buenaventura) | E35: Record client consent under the Data Privacy Act | F35: Functional | G35: Medium | H35: Client record open. | I35: 1. Open Operations > Clients and open a client. 2. Look for a consent capture section and record consent with date and purpose. | J35: Client: any retail client | K35: Consent with date, purpose and channel can be recorded and is shown on the client. | L35: Client Data privacy tab and the privacy API record consent per purpose (processing, marketing, sharing) with channel, evidence and notice version; the consent is shown on the client with its history. Re-test: consent for marketing recorded on CL-2026-00068 (201) and read back. | M35: Pass | N35: BV-DEF-002 (closed) | O35: iorta TechNXT QA | P35: 03 October 2026 | Q35: Re-test of 03 October 2026 after the fix, fresh database with the UAT data set.
A36: BV-SEC-035 | B36: Sign-in and security | C36: Data privacy | D36: System Administrator (BrokerVerse) | E36: Log and answer a data subject access or erasure request | F36: Functional | G36: Medium | H36: Client asks for a copy of personal data. | I36: 1. Look for a data subject request register under Master. 2. Look for an anonymise action on a closed client. | J36: Client: any | K36: Request can be logged and tracked; an inactive client can be anonymised. | L36: Master > Data Privacy: request DSR-2026-00001 logged, due 15 days after receipt (18/10/2026); personal data export produced; anonymise dry run refuses a client with a policy in force and lists the reasons. | M36: Pass | N36: BV-DEF-002 (closed) | O36: iorta TechNXT QA | P36: 03 October 2026 | Q36: Re-test of 03 October 2026 after the fix, fresh database with the UAT data set.
A37: BV-USR-001 | B37: User and role administration | C37: User | D37: System Administrator (BrokerVerse) | E37: Create a user per broker role | F37: Functional | G37: High | H37: Signed in as BrokerVerse. | I37: 1. Open Master > Generals > User Management > User. 2. Click Add User. 3. Enter username, first and last name, e-mail, branch HO, designation and one role. 4. Click Save. 5. Repeat for each persona. | J37: maria.rivera (sales), jose.bernardo (processing), ana.buenaventura (operations), carlo.estrada (claims), liza.quiambao (accounting), teresa.villaroman (accounting-manager); e-mail <user>@example.ph | K37: Each user is saved with the role and listed. A temporary password is shown once for each. | L37: 12 persona users created in the cycle and signed in with their roles. | M37: Pass | O37: iorta TechNXT QA | P37: 04 October 2026 | R37: backend/test/user-access.test.js :: lists, creates and locks users, and reads the audit trail [passed] backend/test/core.test.js :: admin creates a persona user who can then sign in with that role [passed] UAT cycle 03-04 October 2026, phase Set-up (46 passed, 0 failed) Screen check /master/generals/usermanagement/user: opened clean
A38: BV-USR-002 | B38: User and role administration | C38: User | D38: System Administrator (BrokerVerse) | E38: Required fields and e-mail format on Add User | F38: Validation | G38: Medium | H38: Add User form open. | I38: 1. Click Save with all fields empty. 2. Enter e-mail "maria.rivera@" and save. | J38: E-mail: maria.rivera@ | K38: Each required field shows its message. Invalid e-mail is refused. Nothing is saved. | L38: As expected. | M38: Pass | O38: iorta TechNXT QA | P38: 03 October 2026 | R38: backend/test/role-access.test.js :: every create endpoint of the walk answers 400 "Validation failed" with one readable message per field [passed]
A39: BV-USR-003 | B39: User and role administration | C39: User | D39: System Administrator (BrokerVerse) | E39: Duplicate username refused | F39: Negative | G39: Medium | H39: User maria.rivera exists. | I39: 1. Click Add User. 2. Enter username maria.rivera with valid other details. 3. Click Save. | J39: Username: maria.rivera | K39: Save refused with a duplicate username message. | L39: As expected. | M39: Pass | O39: iorta TechNXT QA | P39: 03 October 2026 | Q39: Unique username enforced by the user store. | R39: backend/test/user-access.test.js :: lists, creates and locks users, and reads the audit trail [passed]
A40: BV-USR-004 | B40: User and role administration | C40: User | D40: System Administrator (beatriz.lacson) | E40: Only a System Administrator grants the administrator role | F40: Negative | G40: High | H40: Signed in as a user desk user without System Administrator role. | I40: 1. Open a user and add role system-admin. 2. Click Save. | J40: Target role: system-admin | K40: Save refused. The role list stays unchanged. | L40: As expected. | M40: Pass | O40: iorta TechNXT QA | P40: 03 October 2026 | R40: backend/test/user-access.test.js :: cannot grant the System Administrator role [passed] backend/test/hardening.test.js :: only a System Administrator grants the administrator role or edits it; nobody changes their own roles or status [passed]
...

Sheet Traceability
A1: TC ID | B1: Module | C1: Test Scenario | D1: Status | E1: Backend / front-end test file | F1: Test name | G1: UAT phase | H1: UAT phase result | I1: Screen check (path) | J1: Screen check result
A2: BV-SEC-001 | B2: Sign-in and security | C2: Sign in with a valid user ID and password | D2: Pass | E2: backend/test/core.test.js | F2: rejects a wrong password and accepts the admin | I2: /executive/dashboard | J2: opened clean
A3: BV-SEC-002 | B3: Sign-in and security | C3: Wrong password is refused with a generic message | D3: Pass | E3: backend/test/core.test.js backend/test/security.test.js | F3: rejects a wrong password and accepts the admin exposes sign-in history to administrators and to the user
A4: BV-SEC-003 | B4: Sign-in and security | C4: Unknown user ID gets the same message as a wrong password | D4: Pass | E4: backend/test/security.test.js backend/test/security.test.js | F4: rate limits sign-in per username and per IP (429 + Retry-After) and logs every attempt exposes sign-in history to administrators and to the user
A5: BV-SEC-004 | B5: Sign-in and security | C5: Login with blank User ID and Password | D5: Not Run | E5: brokerverse/src/App.test.js | F5: renders the sign-in screen when signed out
A6: BV-SEC-005 | B6: Sign-in and security | C6: Account locks after the configured number of failed sign-ins | D6: Pass | E6: backend/test/security.test.js backend/test/hardening.test.js | F6: rate limits sign-in per username and per IP (429 + Retry-After) and logs every attempt unlocks a locked account and records it
A7: BV-SEC-006 | B7: Sign-in and security | C7: Administrator unlocks a locked user | D7: Pass | E7: backend/test/hardening.test.js | F7: unlocks a locked account and records it | I7: /master/generals/usermanagement/user | J7: opened clean
A8: BV-SEC-007 | B8: Sign-in and security | C8: Too many sign-in attempts from one address are throttled | D8: Pass | E8: backend/test/security.test.js | F8: rate limits sign-in per username and per IP (429 + Retry-After) and logs every attempt
A9: BV-SEC-008 | B9: Sign-in and security | C9: Change password: rules shown and enforced | D9: Pass | E9: backend/test/security.test.js | F9: enforces length, character classes and history on change-password
A10: BV-SEC-009 | B10: Sign-in and security | C10: New password cannot repeat one of the last 5 passwords | D10: Pass | E10: backend/test/security.test.js | F10: enforces length, character classes and history on change-password
A11: BV-SEC-010 | B11: Sign-in and security | C11: New password must differ from the current one and both entries must match | D11: Pass | E11: backend/test/security.test.js | F11: enforces length, character classes and history on change-password
A12: BV-SEC-011 | B12: Sign-in and security | C12: New user created without a password gets a temporary password that must be changed | D12: Pass | E12: backend/test/hardening.test.js backend/test/core.test.js | F12: generates a policy-compliant temporary password for a user created without one; it must be changed admin creates a persona user who can then sign in with that role | G12: Set-up | H12: 46 passed, 0 failed
A13: BV-SEC-012 | B13: Sign-in and security | C13: Expired password forces a change at sign-in | D13: Pass | E13: backend/test/security.test.js | F13: flags mustChangePassword when the password is older than security.password_max_age_days
A14: BV-SEC-013 | B14: Sign-in and security | C14: Forgot password with a verification code | D14: Blocked | E14: backend/test/configuration.test.js backend/test/hardening.test.js | F14: password reset e-mail and code lifetime follow security.reset_* settings stores reset codes hashed, keeps only the latest valid, withdraws a code after too many wrong entries
A15: BV-SEC-014 | B15: Sign-in and security | C15: Reset code withdrawn after too many wrong entries | D15: Pass | E15: backend/test/hardening.test.js | F15: stores reset codes hashed, keeps only the latest valid, withdraws a code after too many wrong entries
A16: BV-SEC-015 | B16: Sign-in and security | C16: Turn on two-step verification and sign in with the code | D16: Pass | E16: backend/test/security.test.js backend/test/security.test.js | F16: enrols, then requires the code at sign-in; disables with a code implements RFC 6238 / RFC 4226 correctly
A17: BV-SEC-016 | B17: Sign-in and security | C17: Wrong two-step code is refused and checks are rate limited | D17: Pass | E17: backend/test/hardening.test.js backend/test/security.test.js | F17: rate limits two-factor code checks of a signed-in user exposes sign-in history to administrators and to the user
A18: BV-SEC-017 | B18: Sign-in and security | C18: Role that requires two-step verification must enrol before any screen | D18: Pass | E18: backend/test/security.test.js | F18: forces enrolment for roles in security.require_2fa_roles; administrators can reset a user's second factor
A19: BV-SEC-018 | B19: Sign-in and security | C19: Administrator turns off a user's two-step verification | D19: Pass | E19: backend/test/security.test.js | F19: forces enrolment for roles in security.require_2fa_roles; administrators can reset a user's second factor
A20: BV-SEC-019 | B20: Sign-in and security | C20: A non-administrator user desk cannot reset 2FA or lock a System Administrator | D20: Pass | E20: backend/test/hardening.test.js | F20: a non-administrator user desk cannot reset, lock or turn off 2FA of a System Administrator, nor change their own access
A21: BV-SEC-020 | B21: Sign-in and security | C21: Idle session signs out after the configured minutes | D21: Not Run | E21: backend/test/hardening.test.js | F21: defaults: 30-minute access tokens; development keeps its fallbacks
A22: BV-SEC-021 | B22: Sign-in and security | C22: Deactivating a user or changing the role ends access at once | D22: Pass | E22: backend/test/hardening.test.js | F22: ends access at once on deactivation and on role change; refresh issues a token with the new roles
A23: BV-SEC-022 | B23: Sign-in and security | C23: End every session of a user | D23: Pass | E23: backend/test/access-control.test.js | F23: ends every session of a user | I23: /master/generals/usermanagement/access-matrix | J23: opened clean
A24: BV-SEC-023 | B24: Sign-in and security | C24: Reuse of an old refresh token revokes the sign-in | D24: Pass | E24: backend/test/hardening.test.js | F24: detects reuse of a rotated refresh token and revokes the whole sign-in
A25: BV-SEC-024 | B25: Sign-in and security | C25: Sign-in history visible to the administrator and the user | D25: Pass | E25: backend/test/security.test.js | F25: exposes sign-in history to administrators and to the user
A26: BV-SEC-025 | B26: Sign-in and security | C26: Every non-public endpoint refuses a call without a token | D26: Pass | E26: backend/test/hardening.test.js backend/test/hardening.test.js | F26: every non-public route answers 401 without a token declares only the intended public routes
A27: BV-SEC-026 | B27: Sign-in and security | C27: Tokens other than HS256 and default secrets are refused | D27: Pass | E27: backend/test/hardening.test.js backend/test/hardening.test.js | F27: accepts only HS256 tokens refuses missing or default secrets, CORS * and a localhost base URL in production only
A28: BV-SEC-027 | B28: Sign-in and security | C28: Injection probes in search and file fields | D28: Pass | E28: backend/test/hardening.test.js backend/test/hardening.test.js backend/test/configuration.test.js | F28: detects file types from their signature, not from the name or the browser refuses HTML, scripts and unknown binaries; stores the detected type CSV cells written by any module are guarded against spreadsheet formulas
A29: BV-SEC-028 | B29: Sign-in and security | C29: Security headers and request id on every response | D29: Pass | E29: backend/test/security.test.js backend/test/hardening.test.js | F29: adds x-request-id to every response, echoes a caller id and returns it in error bodies answers 500 with a generic message and the request id; client errors keep their message
A30: BV-SEC-029 | B30: Sign-in and security | C30: Upload size limit and global rate limit | D30: Pass | E30: backend/test/hardening.test.js backend/test/hardening.test.js | F30: refuses uploads above UPLOAD_MAX_MB with 413 applies a configurable global API rate limit per user
A31: BV-SEC-030 | B31: Sign-in and security | C31: Tokens and cookies never written to the server log | D31: Pass | E31: backend/test/hardening.test.js | F31: never writes bearer tokens, cookies or link tokens to the log
A32: BV-SEC-031 | B32: Sign-in and security | C32: Document links open only with a session or a signed, unexpired link | D32: Pass | E32: backend/test/hardening.test.js backend/test/hardening.test.js | F32: serves objects only with a bearer header or a signed, unexpired link, with safe headers sends non-image, non-PDF files as attachments; legacy unsafe types as octet-stream
A33: BV-SEC-032 | B33: Sign-in and security | C33: Dependency audit of the release build | D33: Fail
A34: BV-SEC-033 | B34: Sign-in and security | C34: Personal data encrypted at application level | D34: Fail | E34: backend/test/hardening.test.js | F34: encrypts TOTP secrets with DATA_ENCRYPTION_KEY
A35: BV-SEC-034 | B35: Sign-in and security | C35: Record client consent under the Data Privacy Act | D35: Pass
A36: BV-SEC-035 | B36: Sign-in and security | C36: Log and answer a data subject access or erasure request | D36: Pass
A37: BV-USR-001 | B37: User and role administration | C37: Create a user per broker role | D37: Pass | E37: backend/test/user-access.test.js backend/test/core.test.js | F37: lists, creates and locks users, and reads the audit trail admin creates a persona user who can then sign in with that role | G37: Set-up | H37: 46 passed, 0 failed | I37: /master/generals/usermanagement/user | J37: opened clean
A38: BV-USR-002 | B38: User and role administration | C38: Required fields and e-mail format on Add User | D38: Pass | E38: backend/test/role-access.test.js | F38: every create endpoint of the walk answers 400 "Validation failed" with one readable message per field
A39: BV-USR-003 | B39: User and role administration | C39: Duplicate username refused | D39: Pass | E39: backend/test/user-access.test.js | F39: lists, creates and locks users, and reads the audit trail
A40: BV-USR-004 | B40: User and role administration | C40: Only a System Administrator grants the administrator role | D40: Pass | E40: backend/test/user-access.test.js backend/test/hardening.test.js | F40: cannot grant the System Administrator role only a System Administrator grants the administrator role or edits it; nobody changes their own roles or status
...

Sheet Defects and Observations
A1: Defect ID | B1: Title | C1: Module | D1: Severity | E1: Status | F1: Type | G1: Description | H1: Workaround | I1: Target | J1: Linked test cases
A2: BV-DEF-001 | B2: Front-end library react-router has a moderate security advisory (open redirect) | C2: Sign-in and security | D2: Medium | E2: Open | F2: Defect | G2: npm audit of the front-end runtime dependencies reports 2 moderate findings, both in react-router (open redirect). The fixed version is a new major release. Backend runtime dependencies report 0 vulnerabilities. | H2: The application builds its navigation targets from its own menu and routes and does not redirect to addresses taken from the URL. Keep the web server allowing only the application origin. | I2: Next minor release: upgrade react-router to the fixed major version and re-test navigation | J2: BV-SEC-032
A3: BV-DEF-002 | B3: Data privacy features not built: consent capture, data subject request register, anonymisation | C3: Sign-in and security | D3: Medium | E3: Closed | F3: Gap | G3: No screen records client consent (date, purpose, channel), no register tracks data subject access or erasure requests, and there is no function to anonymise an inactive client. Needed for Data Privacy Act compliance processes. | H3: Keep consent forms and the request log outside the system (signed forms filed against the client code; request register kept by the Data Protection Officer). | I3: Closed: fixed on 03 October 2026 (Master > Data Privacy, client Data privacy tab); re-tested BV-SEC-034 and BV-SEC-035 | J3: BV-SEC-034, BV-SEC-035
A4: BV-DEF-003 | B4: Application-level encryption covers only two-step verification secrets | C4: Sign-in and security | D4: Medium | E4: Open | F4: Gap | G4: Only TOTP secrets are encrypted with DATA_ENCRYPTION_KEY. Client personal data (TIN, ID numbers, contact details) is stored in plain database columns. | H4: Use encrypted storage for the database server and backups, restrict database access to the support team, and keep backups encrypted. | I4: Product backlog; field-level encryption of personal identifiers | J4: BV-SEC-033
A5: BV-DEF-004 | B5: Product configurator component list does not show the template; per-template rating factors look duplicated | C5: Product configurator | D5: Low | E5: Closed | F5: Defect | G5: On Product Configurator > Rating Engine (and the other component lists) the rows do not show which template they belong to. Factors with the same name on different templates appear as duplicates. | H5: Open the factor to see its template, or filter by template where the screen offers it. | I5: Closed: fixed on 03 October 2026 (Template column on the component lists); re-tested BV-PCF-005 | J5: BV-PCF-005
A6: BV-OBS-005 | B6: Renewal of a policy expired beyond the grace plus lapsed-renewal window is refused | C6: Renewals | D6: Low | E6: Closed | F6: Observation | G6: A renewal requested for a policy that expired more than grace days plus lapsed-renewal days ago is refused (HTTP 422). This is by design: such a risk is quoted as new business. In the UAT cycle 3 migrated policies were refused this way. | H6: Quote the client as new business from the prospect or client record. | I6: Closed: by design; window settings confirmed with the client at configuration | J6: BV-REN-010
A7: BV-DEF-006 | B7: Premium Taxes & LGU Rates: product list of the charges calculator does not load for Accounting | C7: Masters | D7: Low | E7: Closed | F7: Defect | G7: Screen check of 03 October 2026: signed in as liza.quiambao (accounting) or teresa.villaroman (accounting-manager), Master > Finance > Premium Taxes & LGU Rates opens, but its request GET /placements/options is refused with 403 (the role has no placement read permission). The product drop-down of the charges calculator stays empty. Rules and LGU rates can still be maintained. | H7: Run the charges calculation as the System Administrator, or check the charges on a test quotation. | I7: Closed: fixed on 03 October 2026 (screen reads the product list with a permission Accounting holds); re-tested BV-MST-019, BV-RBA-016, BV-RBA-019 | J7: BV-MST-019, BV-RBA-016, BV-RBA-019
A8: BV-OBS-007 | B8: Menu group Master > Generals > Organization has an address that opens "Page not found" | C8: Screen checks (all menus) | D8: Low | E8: Closed | F8: Observation | G8: The menu group Organization carries its own address (/master/generals/organization) with no screen behind it. Typing the address shows "Page not found" for every user, including the administrator. Company and Branch under it open normally. No data is shown. | H8: Open Company or Branch from the menu. | I8: Closed: fixed on 03 October 2026 (menu groups carry no address) | J8: BV-SCR-018
A9: BV-OBS-008 | B9: Accounts > Incentive > My Programs: Achievement Overview card extends past the right edge at 1440 px | C9: Incentives | D9: Low | E9: Closed | F9: Observation | G9: Screen check at 1440 x 900: the Achievement Overview card on My Programs is wider than the content area and is cut off on the right (administrator and accounting users). | H9: Collapse the side menu or zoom the browser to 90%. | I9: Closed: fixed on 03 October 2026 (card fits at 1440 px); re-tested BV-RBA-016 and BV-RBA-019 | J9: BV-SCR-013, BV-RBA-016, BV-RBA-019
